Workbook

Sheet Instructions
A1: ═══════════════════════════════════════════════════════════
A2: BUFFETT ANALYSIS WORKBOOK — INSTRUCTIONS
A3: ═══════════════════════════════════════════════════════════
A5: HOW TO USE THIS WORKBOOK:
A7: 1. START WITH SHEET '1. Inputs':
A8: - Fill in Company Name, Ticker, CMP, Shares Outstanding
A9: - Set Mode to 'STANDARD' or 'BANK'
A10: - Enter 10 years of financial data (oldest → latest, left → right)
A11: - Yellow cells = YOUR INPUTS (blue font)
A12: - Green cells = Auto-calculated (pulls from other sheets)
A14: 2. COMPUTED SHEETS (2-6, 16) AUTO-CALCULATE:
A15: - Income Statement metrics, margins, growth rates
... A45: EXCEPT in computed sheets where formulas output decimals

Sheet 1. Inputs
A1: BUFFETT ANALYSIS — RAW DATA INPUTS
A2: Company Name:
A3: Ticker / BSE Code:
A4: Current Market Price (CMP): | B4: 0
A5: Shares Outstanding (Diluted, Cr): | B5: 0
A6: Sector:
A7: Mode (STANDARD / BANK): | B7: STANDARD
A9: INCOME STATEMENT DATA
A10: Metric | B10: FY1 (Oldest) | C10: FY2 | D10: FY3 | E10: FY4 | F10: FY5 | G10: FY6 | H10: FY7 | I10: FY8 | J10: FY9 | K10: FY10 (Latest) | L10: TTM
A11: Year Label (e.g. Mar 2016)
A12: Revenue / Total Income (₹ Cr)
A13: Operating Profit / EBITDA (₹ Cr)
A14: Depreciation & Amortisation (₹ Cr)
A15: Interest Expense (₹ Cr)
A16: Profit Before Tax (₹ Cr)
A17: Tax (₹ Cr)
A18: Net Profit (₹ Cr)
A19: EPS (Diluted, ₹)
A20: Dividend Per Share (₹)
A21: --- BANK MODE ONLY ---
A22: Interest Income (₹ Cr)
... A30: BALANCE SHEET DATA
A31: Metric | B31: FY1 (Oldest) | C31: FY2 | D31: FY3 | E31: FY4 | F31: FY5 | G31: FY6 | H31: FY7 | I31: FY8 | J31: FY9 | K31: FY10 (Latest) | L31: TTM
A32: Total Assets (₹ Cr)
A33: Total Liabilities (₹ Cr)
A34: Shareholders' Equity (₹ Cr)
A35: Total Debt / Borrowings (₹ Cr)
A36: Cash & Equivalents (₹ Cr)
A37: Goodwill & Intangibles (₹ Cr)
A38: Reserves & Surplus (₹ Cr)
A39: Book Value Per Share (₹)
A40: --- BANK MODE ONLY ---
A41: Total Advances (₹ Cr)
A42: Total Deposits (₹ Cr)
A43: CASA Deposits (₹ Cr)
... A52: CASH FLOW DATA
A53: Metric | B53: FY1 (Oldest) | C53: FY2 | D53: FY3 | E53: FY4 | F53: FY5 | G53: FY6 | H53: FY7 | I53: FY8 | J53: FY9 | K53: FY10 (Latest) | L53: TTM
A54: Cash from Operations (CFO, ₹ Cr)
A55: Capital Expenditures (₹ Cr)
A56: Cash from Investing (₹ Cr)
...

Sheet 2. Income Statement
A1: SECTION 2: INCOME STATEMENT ANALYSIS — Computed Metrics
A3: Metric | B3: ='1. Inputs'!B11 -> 0 | C3: ='1. Inputs'!C11 -> 0 | D3: ='1. Inputs'!D11 -> 0 | E3: ='1. Inputs'!E11 -> 0 | F3: ='1. Inputs'!F11 -> 0 | G3: ='1. Inputs'!G11 -> 0 | H3: ='1. Inputs'!H11 -> 0 | I3: ='1. Inputs'!I11 -> 0 | ... L3: ='1. Inputs'!L11 -> 0
A4: Revenue (₹ Cr) | B4: ='1. Inputs'!B12 -> 0 | C4: ='1. Inputs'!C12 -> 0 | D4: ='1. Inputs'!D12 -> 0 | E4: ='1. Inputs'!E12 -> 0 | F4: ='1. Inputs'!F12 -> 0 | G4: ='1. Inputs'!G12 -> 0 | H4: ='1. Inputs'!H12 -> 0 | I4: ='1. Inputs'!I12 -> 0 | ... L4: ='1. Inputs'!L12 -> 0
A5: Revenue Growth YoY % | B5: N/A | C5: =IF(OR('1. Inputs'!B12=0,'1. Inputs'!B12=""),"-",('1. Inputs'!C12-'1. Inputs'!B12)/ABS('1. Inputs'!B12)) -> - | D5: =IF(OR('1. Inputs'!C12=0,'1. Inputs'!C12=""),"-",('1. Inputs'!D12-'1. Inputs'!C12)/ABS('1. Inputs'!C12)) -> - | E5: =IF(OR('1. Inputs'!D12=0,'1. Inputs'!D12=""),"-",('1. Inputs'!E12-'1. Inputs'!D12)/ABS('1. Inputs'!D12)) -> - | F5: =IF(OR('1. Inputs'!E12=0,'1. Inputs'!E12=""),"-",('1. Inputs'!F12-'1. Inputs'!E12)/ABS('1. Inputs'!E12)) -> - | G5: =IF(OR('1. Inputs'!F12=0,'1. Inputs'!F12=""),"-",('1. Inputs'!G12-'1. Inputs'!F12)/ABS('1. Inputs'!F12)) -> - | H5: =IF(OR('1. Inputs'!G12=0,'1. Inputs'!G12=""),"-",('1. Inputs'!H12-'1. Inputs'!G12)/ABS('1. Inputs'!G12)) -> - | I5: =IF(OR('1. Inputs'!H12=0,'1. Inputs'!H12=""),"-",('1. Inputs'!I12-'1. Inputs'!H12)/ABS('1. Inputs'!H12)) -> - | J5: =IF(OR('1. Inputs'!I12=0,'1. Inputs'!I12=""),"-",('1. Inputs'!J12-'1. Inputs'!I12)/ABS('1. Inputs'!I12)) -> - | ... L5: =IF(OR('1. Inputs'!K12=0,'1. Inputs'!K12=""),"-",('1. Inputs'!L12-'1. Inputs'!K12)/ABS('1. Inputs'!K12)) -> -
A6: Operating Profit / EBITDA (₹ Cr) | B6: ='1. Inputs'!B13 -> 0 | C6: ='1. Inputs'!C13 -> 0 | D6: ='1. Inputs'!D13 -> 0 | E6: ='1. Inputs'!E13 -> 0 | F6: ='1. Inputs'!F13 -> 0 | G6: ='1. Inputs'!G13 -> 0 | H6: ='1. Inputs'!H13 -> 0 | I6: ='1. Inputs'!I13 -> 0 | ... L6: ='1. Inputs'!L13 -> 0
A7: EBITDA Margin % | B7: =IF(OR('1. Inputs'!B12=0,'1. Inputs'!B12=""),"-",'1. Inputs'!B13/'1. Inputs'!B12) -> - | C7: =IF(OR('1. Inputs'!C12=0,'1. Inputs'!C12=""),"-",'1. Inputs'!C13/'1. Inputs'!C12) -> - | D7: =IF(OR('1. Inputs'!D12=0,'1. Inputs'!D12=""),"-",'1. Inputs'!D13/'1. Inputs'!D12) -> - | E7: =IF(OR('1. Inputs'!E12=0,'1. Inputs'!E12=""),"-",'1. Inputs'!E13/'1. Inputs'!E12) -> - | F7: =IF(OR('1. Inputs'!F12=0,'1. Inputs'!F12=""),"-",'1. Inputs'!F13/'1. Inputs'!F12) -> - | G7: =IF(OR('1. Inputs'!G12=0,'1. Inputs'!G12=""),"-",'1. Inputs'!G13/'1. Inputs'!G12) -> - | H7: =IF(OR('1. Inputs'!H12=0,'1. Inputs'!H12=""),"-",'1. Inputs'!H13/'1. Inputs'!H12) -> - | I7: =IF(OR('1. Inputs'!I12=0,'1. Inputs'!I12=""),"-",'1. Inputs'!I13/'1. Inputs'!I12) -> - | ... L7: =IF(OR('1. Inputs'!L12=0,'1. Inputs'!L12=""),"-",'1. Inputs'!L13/'1. Inputs'!L12) -> -
A8: Depreciation & Amort. (₹ Cr) | B8: ='1. Inputs'!B14 -> 0 | C8: ='1. Inputs'!C14 -> 0 | D8: ='1. Inputs'!D14 -> 0 | E8: ='1. Inputs'!E14 -> 0 | F8: ='1. Inputs'!F14 -> 0 | G8: ='1. Inputs'!G14 -> 0 | H8: ='1. Inputs'!H14 -> 0 | I8: ='1. Inputs'!I14 -> 0 | ... L8: ='1. Inputs'!L14 -> 0
A9: EBIT (₹ Cr) | B9: ='1. Inputs'!B13-'1. Inputs'!B14 -> 0 | C9: ='1. Inputs'!C13-'1. Inputs'!C14 -> 0 | D9: ='1. Inputs'!D13-'1. Inputs'!D14 -> 0 | E9: ='1. Inputs'!E13-'1. Inputs'!E14 -> 0 | F9: ='1. Inputs'!F13-'1. Inputs'!F14 -> 0 | G9: ='1. Inputs'!G13-'1. Inputs'!G14 -> 0 | H9: ='1. Inputs'!H13-'1. Inputs'!H14 -> 0 | I9: ='1. Inputs'!I13-'1. Inputs'!I14 -> 0 | ... L9: ='1. Inputs'!L13-'1. Inputs'!L14 -> 0
A10: Interest Expense (₹ Cr) | B10: ='1. Inputs'!B15 -> 0 | C10: ='1. Inputs'!C15 -> 0 | D10: ='1. Inputs'!D15 -> 0 | E10: ='1. Inputs'!E15 -> 0 | F10: ='1. Inputs'!F15 -> 0 | G10: ='1. Inputs'!G15 -> 0 | H10: ='1. Inputs'!H15 -> 0 | I10: ='1. Inputs'!I15 -> 0 | ... L10: ='1. Inputs'!L15 -> 0
A11: PBT (₹ Cr) | B11: ='1. Inputs'!B16 -> 0 | C11: ='1. Inputs'!C16 -> 0 | D11: ='1. Inputs'!D16 -> 0 | E11: ='1. Inputs'!E16 -> 0 | F11: ='1. Inputs'!F16 -> 0 | G11: ='1. Inputs'!G16 -> 0 | H11: ='1. Inputs'!H16 -> 0 | I11: ='1. Inputs'!I16 -> 0 | ... L11: ='1. Inputs'!L16 -> 0
A12: Tax (₹ Cr) | B12: ='1. Inputs'!B17 -> 0 | C12: ='1. Inputs'!C17 -> 0 | D12: ='1. Inputs'!D17 -> 0 | E12: ='1. Inputs'!E17 -> 0 | F12: ='1. Inputs'!F17 -> 0 | G12: ='1. Inputs'!G17 -> 0 | H12: ='1. Inputs'!H17 -> 0 | I12: ='1. Inputs'!I17 -> 0 | ... L12: ='1. Inputs'!L17 -> 0
A13: Effective Tax Rate % | B13: =IF(OR('1. Inputs'!B16=0,'1. Inputs'!B16=""),"-",'1. Inputs'!B17/'1. Inputs'!B16) -> - | C13: =IF(OR('1. Inputs'!C16=0,'1. Inputs'!C16=""),"-",'1. Inputs'!C17/'1. Inputs'!C16) -> - | D13: =IF(OR('1. Inputs'!D16=0,'1. Inputs'!D16=""),"-",'1. Inputs'!D17/'1. Inputs'!D16) -> - | E13: =IF(OR('1. Inputs'!E16=0,'1. Inputs'!E16=""),"-",'1. Inputs'!E17/'1. Inputs'!E16) -> - | F13: =IF(OR('1. Inputs'!F16=0,'1. Inputs'!F16=""),"-",'1. Inputs'!F17/'1. Inputs'!F16) -> - | G13: =IF(OR('1. Inputs'!G16=0,'1. Inputs'!G16=""),"-",'1. Inputs'!G17/'1. Inputs'!G16) -> - | H13: =IF(OR('1. Inputs'!H16=0,'1. Inputs'!H16=""),"-",'1. Inputs'!H17/'1. Inputs'!H16) -> - | I13: =IF(OR('1. Inputs'!I16=0,'1. Inputs'!I16=""),"-",'1. Inputs'!I17/'1. Inputs'!I16) -> - | ... L13: =IF(OR('1. Inputs'!L16=0,'1. Inputs'!L16=""),"-",'1. Inputs'!L17/'1. Inputs'!L16) -> -
A14: Net Profit (₹ Cr) | B14: ='1. Inputs'!B18 -> 0 | C14: ='1. Inputs'!C18 -> 0 | D14: ='1. Inputs'!D18 -> 0 | E14: ='1. Inputs'!E18 -> 0 | F14: ='1. Inputs'!F18 -> 0 | G14: ='1. Inputs'!G18 -> 0 | H14: ='1. Inputs'!H18 -> 0 | I14: ='1. Inputs'!I18 -> 0 | ... L14: ='1. Inputs'!L18 -> 0
A15: Net Profit Margin % | B15: =IF(OR('1. Inputs'!B12=0,'1. Inputs'!B12=""),"-",'1. Inputs'!B18/'1. Inputs'!B12) -> - | C15: =IF(OR('1. Inputs'!C12=0,'1. Inputs'!C12=""),"-",'1. Inputs'!C18/'1. Inputs'!C12) -> - | D15: =IF(OR('1. Inputs'!D12=0,'1. Inputs'!D12=""),"-",'1. Inputs'!D18/'1. Inputs'!D12) -> - | E15: =IF(OR('1. Inputs'!E12=0,'1. Inputs'!E12=""),"-",'1. Inputs'!E18/'1. Inputs'!E12) -> - | F15: =IF(OR('1. Inputs'!F12=0,'1. Inputs'!F12=""),"-",'1. Inputs'!F18/'1. Inputs'!F12) -> - | G15: =IF(OR('1. Inputs'!G12=0,'1. Inputs'!G12=""),"-",'1. Inputs'!G18/'1. Inputs'!G12) -> - | H15: =IF(OR('1. Inputs'!H12=0,'1. Inputs'!H12=""),"-",'1. Inputs'!H18/'1. Inputs'!H12) -> - | I15: =IF(OR('1. Inputs'!I12=0,'1. Inputs'!I12=""),"-",'1. Inputs'!I18/'1. Inputs'!I12) -> - | ... L15: =IF(OR('1. Inputs'!L12=0,'1. Inputs'!L12=""),"-",'1. Inputs'!L18/'1. Inputs'!L12) -> -
A16: Net Profit Growth YoY % | B16: N/A | C16: =IF(OR('1. Inputs'!B18=0,'1. Inputs'!B18=""),"-",('1. Inputs'!C18-'1. Inputs'!B18)/ABS('1. Inputs'!B18)) -> - | D16: =IF(OR('1. Inputs'!C18=0,'1. Inputs'!C18=""),"-",('1. Inputs'!D18-'1. Inputs'!C18)/ABS('1. Inputs'!C18)) -> - | E16: =IF(OR('1. Inputs'!D18=0,'1. Inputs'!D18=""),"-",('1. Inputs'!E18-'1. Inputs'!D18)/ABS('1. Inputs'!D18)) -> - | F16: =IF(OR('1. Inputs'!E18=0,'1. Inputs'!E18=""),"-",('1. Inputs'!F18-'1. Inputs'!E18)/ABS('1. Inputs'!E18)) -> - | G16: =IF(OR('1. Inputs'!F18=0,'1. Inputs'!F18=""),"-",('1. Inputs'!G18-'1. Inputs'!F18)/ABS('1. Inputs'!F18)) -> - | H16: =IF(OR('1. Inputs'!G18=0,'1. Inputs'!G18=""),"-",('1. Inputs'!H18-'1. Inputs'!G18)/ABS('1. Inputs'!G18)) -> - | I16: =IF(OR('1. Inputs'!H18=0,'1. Inputs'!H18=""),"-",('1. Inputs'!I18-'1. Inputs'!H18)/ABS('1. Inputs'!H18)) -> - | J16: =IF(OR('1. Inputs'!I18=0,'1. Inputs'!I18=""),"-",('1. Inputs'!J18-'1. Inputs'!I18)/ABS('1. Inputs'!I18)) -> - | ... L16: =IF(OR('1. Inputs'!K18=0,'1. Inputs'!K18=""),"-",('1. Inputs'!L18-'1. Inputs'!K18)/ABS('1. Inputs'!K18)) -> -
A17: EPS Diluted (₹) | B17: ='1. Inputs'!B19 -> 0 | C17: ='1. Inputs'!C19 -> 0 | D17: ='1. Inputs'!D19 -> 0 | E17: ='1. Inputs'!E19 -> 0 | F17: ='1. Inputs'!F19 -> 0 | G17: ='1. Inputs'!G19 -> 0 | H17: ='1. Inputs'!H19 -> 0 | I17: ='1. Inputs'!I19 -> 0 | ... L17: ='1. Inputs'!L19 -> 0
A18: EPS Growth YoY % | B18: N/A | C18: =IF(OR('1. Inputs'!B19=0,'1. Inputs'!B19=""),"-",('1. Inputs'!C19-'1. Inputs'!B19)/ABS('1. Inputs'!B19)) -> - | D18: =IF(OR('1. Inputs'!C19=0,'1. Inputs'!C19=""),"-",('1. Inputs'!D19-'1. Inputs'!C19)/ABS('1. Inputs'!C19)) -> - | E18: =IF(OR('1. Inputs'!D19=0,'1. Inputs'!D19=""),"-",('1. Inputs'!E19-'1. Inputs'!D19)/ABS('1. Inputs'!D19)) -> - | F18: =IF(OR('1. Inputs'!E19=0,'1. Inputs'!E19=""),"-",('1. Inputs'!F19-'1. Inputs'!E19)/ABS('1. Inputs'!E19)) -> - | G18: =IF(OR('1. Inputs'!F19=0,'1. Inputs'!F19=""),"-",('1. Inputs'!G19-'1. Inputs'!F19)/ABS('1. Inputs'!F19)) -> - | H18: =IF(OR('1. Inputs'!G19=0,'1. Inputs'!G19=""),"-",('1. Inputs'!H19-'1. Inputs'!G19)/ABS('1. Inputs'!G19)) -> - | I18: =IF(OR('1. Inputs'!H19=0,'1. Inputs'!H19=""),"-",('1. Inputs'!I19-'1. Inputs'!H19)/ABS('1. Inputs'!H19)) -> - | J18: =IF(OR('1. Inputs'!I19=0,'1. Inputs'!I19=""),"-",('1. Inputs'!J19-'1. Inputs'!I19)/ABS('1. Inputs'!I19)) -> - | ... L18: =IF(OR('1. Inputs'!K19=0,'1. Inputs'!K19=""),"-",('1. Inputs'!L19-'1. Inputs'!K19)/ABS('1. Inputs'!K19)) -> -
A19: DPS (₹) | B19: ='1. Inputs'!B20 -> 0 | C19: ='1. Inputs'!C20 -> 0 | D19: ='1. Inputs'!D20 -> 0 | E19: ='1. Inputs'!E20 -> 0 | F19: ='1. Inputs'!F20 -> 0 | G19: ='1. Inputs'!G20 -> 0 | H19: ='1. Inputs'!H20 -> 0 | I19: ='1. Inputs'!I20 -> 0 | ... L19: ='1. Inputs'!L20 -> 0
A20: Payout Ratio % | B20: =IF(OR('1. Inputs'!B19=0,'1. Inputs'!B19=""),"-",'1. Inputs'!B20/'1. Inputs'!B19) -> - | C20: =IF(OR('1. Inputs'!C19=0,'1. Inputs'!C19=""),"-",'1. Inputs'!C20/'1. Inputs'!C19) -> - | D20: =IF(OR('1. Inputs'!D19=0,'1. Inputs'!D19=""),"-",'1. Inputs'!D20/'1. Inputs'!D19) -> - | E20: =IF(OR('1. Inputs'!E19=0,'1. Inputs'!E19=""),"-",'1. Inputs'!E20/'1. Inputs'!E19) -> - | F20: =IF(OR('1. Inputs'!F19=0,'1. Inputs'!F19=""),"-",'1. Inputs'!F20/'1. Inputs'!F19) -> - | G20: =IF(OR('1. Inputs'!G19=0,'1. Inputs'!G19=""),"-",'1. Inputs'!G20/'1. Inputs'!G19) -> - | H20: =IF(OR('1. Inputs'!H19=0,'1. Inputs'!H19=""),"-",'1. Inputs'!H20/'1. Inputs'!H19) -> - | I20: =IF(OR('1. Inputs'!I19=0,'1. Inputs'!I19=""),"-",'1. Inputs'!I20/'1. Inputs'!I19) -> - | ... L20: =IF(OR('1. Inputs'!L19=0,'1. Inputs'!L19=""),"-",'1. Inputs'!L20/'1. Inputs'!L19) -> -

Sheet 3. Balance Sheet
A1: SECTION 3: BALANCE SHEET — Computed Metrics
A3: Metric | B3: ='1. Inputs'!B11 -> 0 | C3: ='1. Inputs'!C11 -> 0 | D3: ='1. Inputs'!D11 -> 0 | E3: ='1. Inputs'!E11 -> 0 | F3: ='1. Inputs'!F11 -> 0 | G3: ='1. Inputs'!G11 -> 0 | H3: ='1. Inputs'!H11 -> 0 | I3: ='1. Inputs'!I11 -> 0 | ... L3: ='1. Inputs'!L11 -> 0
A4: Total Assets (₹ Cr) | B4: ='1. Inputs'!B32 -> 0 | C4: ='1. Inputs'!C32 -> 0 | D4: ='1. Inputs'!D32 -> 0 | E4: ='1. Inputs'!E32 -> 0 | F4: ='1. Inputs'!F32 -> 0 | G4: ='1. Inputs'!G32 -> 0 | H4: ='1. Inputs'!H32 -> 0 | I4: ='1. Inputs'!I32 -> 0 | ... L4: ='1. Inputs'!L32 -> 0
A5: Total Assets Growth % | B5: N/A | C5: =IF(OR('1. Inputs'!B32=0,'1. Inputs'!B32=""),"-",('1. Inputs'!C32-'1. Inputs'!B32)/ABS('1. Inputs'!B32)) -> - | D5: =IF(OR('1. Inputs'!C32=0,'1. Inputs'!C32=""),"-",('1. Inputs'!D32-'1. Inputs'!C32)/ABS('1. Inputs'!C32)) -> - | E5: =IF(OR('1. Inputs'!D32=0,'1. Inputs'!D32=""),"-",('1. Inputs'!E32-'1. Inputs'!D32)/ABS('1. Inputs'!D32)) -> - | F5: =IF(OR('1. Inputs'!E32=0,'1. Inputs'!E32=""),"-",('1. Inputs'!F32-'1. Inputs'!E32)/ABS('1. Inputs'!E32)) -> - | G5: =IF(OR('1. Inputs'!F32=0,'1. Inputs'!F32=""),"-",('1. Inputs'!G32-'1. Inputs'!F32)/ABS('1. Inputs'!F32)) -> - | H5: =IF(OR('1. Inputs'!G32=0,'1. Inputs'!G32=""),"-",('1. Inputs'!H32-'1. Inputs'!G32)/ABS('1. Inputs'!G32)) -> - | I5: =IF(OR('1. Inputs'!H32=0,'1. Inputs'!H32=""),"-",('1. Inputs'!I32-'1. Inputs'!H32)/ABS('1. Inputs'!H32)) -> - | J5: =IF(OR('1. Inputs'!I32=0,'1. Inputs'!I32=""),"-",('1. Inputs'!J32-'1. Inputs'!I32)/ABS('1. Inputs'!I32)) -> - | ... L5: =IF(OR('1. Inputs'!K32=0,'1. Inputs'!K32=""),"-",('1. Inputs'!L32-'1. Inputs'!K32)/ABS('1. Inputs'!K32)) -> -
A6: Total Liabilities (₹ Cr) | B6: ='1. Inputs'!B33 -> 0 | C6: ='1. Inputs'!C33 -> 0 | D6: ='1. Inputs'!D33 -> 0 | E6: ='1. Inputs'!E33 -> 0 | F6: ='1. Inputs'!F33 -> 0 | G6: ='1. Inputs'!G33 -> 0 | H6: ='1. Inputs'!H33 -> 0 | I6: ='1. Inputs'!I33 -> 0 | ... L6: ='1. Inputs'!L33 -> 0
A7: Shareholders' Equity (₹ Cr) | B7: ='1. Inputs'!B34 -> 0 | C7: ='1. Inputs'!C34 -> 0 | D7: ='1. Inputs'!D34 -> 0 | E7: ='1. Inputs'!E34 -> 0 | F7: ='1. Inputs'!F34 -> 0 | G7: ='1. Inputs'!G34 -> 0 | H7: ='1. Inputs'!H34 -> 0 | I7: ='1. Inputs'!I34 -> 0 | ... L7: ='1. Inputs'!L34 -> 0
A8: Equity Growth % | B8: N/A | C8: =IF(OR('1. Inputs'!B34=0,'1. Inputs'!B34=""),"-",('1. Inputs'!C34-'1. Inputs'!B34)/ABS('1. Inputs'!B34)) -> - | D8: =IF(OR('1. Inputs'!C34=0,'1. Inputs'!C34=""),"-",('1. Inputs'!D34-'1. Inputs'!C34)/ABS('1. Inputs'!C34)) -> - | E8: =IF(OR('1. Inputs'!D34=0,'1. Inputs'!D34=""),"-",('1. Inputs'!E34-'1. Inputs'!D34)/ABS('1. Inputs'!D34)) -> - | F8: =IF(OR('1. Inputs'!E34=0,'1. Inputs'!E34=""),"-",('1. Inputs'!F34-'1. Inputs'!E34)/ABS('1. Inputs'!E34)) -> - | G8: =IF(OR('1. Inputs'!F34=0,'1. Inputs'!F34=""),"-",('1. Inputs'!G34-'1. Inputs'!F34)/ABS('1. Inputs'!F34)) -> - | H8: =IF(OR('1. Inputs'!G34=0,'1. Inputs'!G34=""),"-",('1. Inputs'!H34-'1. Inputs'!G34)/ABS('1. Inputs'!G34)) -> - | I8: =IF(OR('1. Inputs'!H34=0,'1. Inputs'!H34=""),"-",('1. Inputs'!I34-'1. Inputs'!H34)/ABS('1. Inputs'!H34)) -> - | J8: =IF(OR('1. Inputs'!I34=0,'1. Inputs'!I34=""),"-",('1. Inputs'!J34-'1. Inputs'!I34)/ABS('1. Inputs'!I34)) -> - | ... L8: =IF(OR('1. Inputs'!K34=0,'1. Inputs'!K34=""),"-",('1. Inputs'!L34-'1. Inputs'!K34)/ABS('1. Inputs'!K34)) -> -
A9: Total Debt (₹ Cr) | B9: ='1. Inputs'!B35 -> 0 | C9: ='1. Inputs'!C35 -> 0 | D9: ='1. Inputs'!D35 -> 0 | E9: ='1. Inputs'!E35 -> 0 | F9: ='1. Inputs'!F35 -> 0 | G9: ='1. Inputs'!G35 -> 0 | H9: ='1. Inputs'!H35 -> 0 | I9: ='1. Inputs'!I35 -> 0 | ... L9: ='1. Inputs'!L35 -> 0
A10: Cash & Equiv (₹ Cr) | B10: ='1. Inputs'!B36 -> 0 | C10: ='1. Inputs'!C36 -> 0 | D10: ='1. Inputs'!D36 -> 0 | E10: ='1. Inputs'!E36 -> 0 | F10: ='1. Inputs'!F36 -> 0 | G10: ='1. Inputs'!G36 -> 0 | H10: ='1. Inputs'!H36 -> 0 | I10: ='1. Inputs'!I36 -> 0 | ... L10: ='1. Inputs'!L36 -> 0
A11: Net Debt (₹ Cr) | B11: ='1. Inputs'!B35-'1. Inputs'!B36 -> 0 | C11: ='1. Inputs'!C35-'1. Inputs'!C36 -> 0 | D11: ='1. Inputs'!D35-'1. Inputs'!D36 -> 0 | E11: ='1. Inputs'!E35-'1. Inputs'!E36 -> 0 | F11: ='1. Inputs'!F35-'1. Inputs'!F36 -> 0 | G11: ='1. Inputs'!G35-'1. Inputs'!G36 -> 0 | H11: ='1. Inputs'!H35-'1. Inputs'!H36 -> 0 | I11: ='1. Inputs'!I35-'1. Inputs'!I36 -> 0 | ... L11: ='1. Inputs'!L35-'1. Inputs'!L36 -> 0
A12: Goodwill (₹ Cr) | B12: ='1. Inputs'!B37 -> 0 | C12: ='1. Inputs'!C37 -> 0 | D12: ='1. Inputs'!D37 -> 0 | E12: ='1. Inputs'!E37 -> 0 | F12: ='1. Inputs'!F37 -> 0 | G12: ='1. Inputs'!G37 -> 0 | H12: ='1. Inputs'!H37 -> 0 | I12: ='1. Inputs'!I37 -> 0 | ... L12: ='1. Inputs'!L37 -> 0
A13: Book Value Per Share (₹) | B13: ='1. Inputs'!B39 -> 0 | C13: ='1. Inputs'!C39 -> 0 | D13: ='1. Inputs'!D39 -> 0 | E13: ='1. Inputs'!E39 -> 0 | F13: ='1. Inputs'!F39 -> 0 | G13: ='1. Inputs'!G39 -> 0 | H13: ='1. Inputs'!H39 -> 0 | I13: ='1. Inputs'!I39 -> 0 | ... L13: ='1. Inputs'!L39 -> 0
A14: BVPS Growth % | B14: N/A | C14: =IF(OR('1. Inputs'!B39=0,'1. Inputs'!B39=""),"-",('1. Inputs'!C39-'1. Inputs'!B39)/ABS('1. Inputs'!B39)) -> - | D14: =IF(OR('1. Inputs'!C39=0,'1. Inputs'!C39=""),"-",('1. Inputs'!D39-'1. Inputs'!C39)/ABS('1. Inputs'!C39)) -> - | E14: =IF(OR('1. Inputs'!D39=0,'1. Inputs'!D39=""),"-",('1. Inputs'!E39-'1. Inputs'!D39)/ABS('1. Inputs'!D39)) -> - | F14: =IF(OR('1. Inputs'!E39=0,'1. Inputs'!E39=""),"-",('1. Inputs'!F39-'1. Inputs'!E39)/ABS('1. Inputs'!E39)) -> - | G14: =IF(OR('1. Inputs'!F39=0,'1. Inputs'!F39=""),"-",('1. Inputs'!G39-'1. Inputs'!F39)/ABS('1. Inputs'!F39)) -> - | H14: =IF(OR('1. Inputs'!G39=0,'1. Inputs'!G39=""),"-",('1. Inputs'!H39-'1. Inputs'!G39)/ABS('1. Inputs'!G39)) -> - | I14: =IF(OR('1. Inputs'!H39=0,'1. Inputs'!H39=""),"-",('1. Inputs'!I39-'1. Inputs'!H39)/ABS('1. Inputs'!H39)) -> - | J14: =IF(OR('1. Inputs'!I39=0,'1. Inputs'!I39=""),"-",('1. Inputs'!J39-'1. Inputs'!I39)/ABS('1. Inputs'!I39)) -> - | ... L14: =IF(OR('1. Inputs'!K39=0,'1. Inputs'!K39=""),"-",('1. Inputs'!L39-'1. Inputs'!K39)/ABS('1. Inputs'!K39)) -> -
A15: Tangible BVPS (₹) | B15: =IF('1. Inputs'!$B$5=0,"-",('1. Inputs'!B34-'1. Inputs'!B37)/'1. Inputs'!$B$5) -> - | C15: =IF('1. Inputs'!$B$5=0,"-",('1. Inputs'!C34-'1. Inputs'!C37)/'1. Inputs'!$B$5) -> - | D15: =IF('1. Inputs'!$B$5=0,"-",('1. Inputs'!D34-'1. Inputs'!D37)/'1. Inputs'!$B$5) -> - | E15: =IF('1. Inputs'!$B$5=0,"-",('1. Inputs'!E34-'1. Inputs'!E37)/'1. Inputs'!$B$5) -> - | F15: =IF('1. Inputs'!$B$5=0,"-",('1. Inputs'!F34-'1. Inputs'!F37)/'1. Inputs'!$B$5) -> - | G15: =IF('1. Inputs'!$B$5=0,"-",('1. Inputs'!G34-'1. Inputs'!G37)/'1. Inputs'!$B$5) -> - | H15: =IF('1. Inputs'!$B$5=0,"-",('1. Inputs'!H34-'1. Inputs'!H37)/'1. Inputs'!$B$5) -> - | I15: =IF('1. Inputs'!$B$5=0,"-",('1. Inputs'!I34-'1. Inputs'!I37)/'1. Inputs'!$B$5) -> - | ... L15: =IF('1. Inputs'!$B$5=0,"-",('1. Inputs'!L34-'1. Inputs'!L37)/'1. Inputs'!$B$5) -> -
A16: Debt/Equity Ratio | B16: =IF(OR('1. Inputs'!B34=0,'1. Inputs'!B34=""),"-",'1. Inputs'!B35/'1. Inputs'!B34) -> - | C16: =IF(OR('1. Inputs'!C34=0,'1. Inputs'!C34=""),"-",'1. Inputs'!C35/'1. Inputs'!C34) -> - | D16: =IF(OR('1. Inputs'!D34=0,'1. Inputs'!D34=""),"-",'1. Inputs'!D35/'1. Inputs'!D34) -> - | E16: =IF(OR('1. Inputs'!E34=0,'1. Inputs'!E34=""),"-",'1. Inputs'!E35/'1. Inputs'!E34) -> - | F16: =IF(OR('1. Inputs'!F34=0,'1. Inputs'!F34=""),"-",'1. Inputs'!F35/'1. Inputs'!F34) -> - | G16: =IF(OR('1. Inputs'!G34=0,'1. Inputs'!G34=""),"-",'1. Inputs'!G35/'1. Inputs'!G34) -> - | H16: =IF(OR('1. Inputs'!H34=0,'1. Inputs'!H34=""),"-",'1. Inputs'!H35/'1. Inputs'!H34) -> - | I16: =IF(OR('1. Inputs'!I34=0,'1. Inputs'!I34=""),"-",'1. Inputs'!I35/'1. Inputs'!I34) -> - | ... L16: =IF(OR('1. Inputs'!L34=0,'1. Inputs'!L34=""),"-",'1. Inputs'!L35/'1. Inputs'!L34) -> -
A17: Debt/EBITDA Ratio | B17: =IF(OR('1. Inputs'!B13=0,'1. Inputs'!B13=""),"-",'1. Inputs'!B35/'1. Inputs'!B13) -> - | C17: =IF(OR('1. Inputs'!C13=0,'1. Inputs'!C13=""),"-",'1. Inputs'!C35/'1. Inputs'!C13) -> - | D17: =IF(OR('1. Inputs'!D13=0,'1. Inputs'!D13=""),"-",'1. Inputs'!D35/'1. Inputs'!D13) -> - | E17: =IF(OR('1. Inputs'!E13=0,'1. Inputs'!E13=""),"-",'1. Inputs'!E35/'1. Inputs'!E13) -> - | F17: =IF(OR('1. Inputs'!F13=0,'1. Inputs'!F13=""),"-",'1. Inputs'!F35/'1. Inputs'!F13) -> - | G17: =IF(OR('1. Inputs'!G13=0,'1. Inputs'!G13=""),"-",'1. Inputs'!G35/'1. Inputs'!G13) -> - | H17: =IF(OR('1. Inputs'!H13=0,'1. Inputs'!H13=""),"-",'1. Inputs'!H35/'1. Inputs'!H13) -> - | I17: =IF(OR('1. Inputs'!I13=0,'1. Inputs'!I13=""),"-",'1. Inputs'!I35/'1. Inputs'!I13) -> - | ... L17: =IF(OR('1. Inputs'!L13=0,'1. Inputs'!L13=""),"-",'1. Inputs'!L35/'1. Inputs'!L13) -> -
A18: Net Debt/EBITDA | B18: =IF(OR('1. Inputs'!B13=0,'1. Inputs'!B13=""),"-",('1. Inputs'!B35-'1. Inputs'!B36)/'1. Inputs'!B13) -> - | C18: =IF(OR('1. Inputs'!C13=0,'1. Inputs'!C13=""),"-",('1. Inputs'!C35-'1. Inputs'!C36)/'1. Inputs'!C13) -> - | D18: =IF(OR('1. Inputs'!D13=0,'1. Inputs'!D13=""),"-",('1. Inputs'!D35-'1. Inputs'!D36)/'1. Inputs'!D13) -> - | E18: =IF(OR('1. Inputs'!E13=0,'1. Inputs'!E13=""),"-",('1. Inputs'!E35-'1. Inputs'!E36)/'1. Inputs'!E13) -> - | F18: =IF(OR('1. Inputs'!F13=0,'1. Inputs'!F13=""),"-",('1. Inputs'!F35-'1. Inputs'!F36)/'1. Inputs'!F13) -> - | G18: =IF(OR('1. Inputs'!G13=0,'1. Inputs'!G13=""),"-",('1. Inputs'!G35-'1. Inputs'!G36)/'1. Inputs'!G13) -> - | H18: =IF(OR('1. Inputs'!H13=0,'1. Inputs'!H13=""),"-",('1. Inputs'!H35-'1. Inputs'!H36)/'1. Inputs'!H13) -> - | I18: =IF(OR('1. Inputs'!I13=0,'1. Inputs'!I13=""),"-",('1. Inputs'!I35-'1. Inputs'!I36)/'1. Inputs'!I13) -> - | ... L18: =IF(OR('1. Inputs'!L13=0,'1. Inputs'!L13=""),"-",('1. Inputs'!L35-'1. Inputs'!L36)/'1. Inputs'!L13) -> -

Sheet 4. Cash Flow
A1: SECTION 4: CASH FLOW ANALYSIS — Computed Metrics
A3: Metric | B3: ='1. Inputs'!B11 -> 0 | C3: ='1. Inputs'!C11 -> 0 | D3: ='1. Inputs'!D11 -> 0 | E3: ='1. Inputs'!E11 -> 0 | F3: ='1. Inputs'!F11 -> 0 | G3: ='1. Inputs'!G11 -> 0 | H3: ='1. Inputs'!H11 -> 0 | I3: ='1. Inputs'!I11 -> 0 | ... L3: ='1. Inputs'!L11 -> 0
A4: CFO (₹ Cr) | B4: ='1. Inputs'!B54 -> 0 | C4: ='1. Inputs'!C54 -> 0 | D4: ='1. Inputs'!D54 -> 0 | E4: ='1. Inputs'!E54 -> 0 | F4: ='1. Inputs'!F54 -> 0 | G4: ='1. Inputs'!G54 -> 0 | H4: ='1. Inputs'!H54 -> 0 | I4: ='1. Inputs'!I54 -> 0 | ... L4: ='1. Inputs'!L54 -> 0
A5: CFO Growth % | B5: N/A | C5: =IF(OR('1. Inputs'!B54=0,'1. Inputs'!B54=""),"-",('1. Inputs'!C54-'1. Inputs'!B54)/ABS('1. Inputs'!B54)) -> - | D5: =IF(OR('1. Inputs'!C54=0,'1. Inputs'!C54=""),"-",('1. Inputs'!D54-'1. Inputs'!C54)/ABS('1. Inputs'!C54)) -> - | E5: =IF(OR('1. Inputs'!D54=0,'1. Inputs'!D54=""),"-",('1. Inputs'!E54-'1. Inputs'!D54)/ABS('1. Inputs'!D54)) -> - | F5: =IF(OR('1. Inputs'!E54=0,'1. Inputs'!E54=""),"-",('1. Inputs'!F54-'1. Inputs'!E54)/ABS('1. Inputs'!E54)) -> - | G5: =IF(OR('1. Inputs'!F54=0,'1. Inputs'!F54=""),"-",('1. Inputs'!G54-'1. Inputs'!F54)/ABS('1. Inputs'!F54)) -> - | H5: =IF(OR('1. Inputs'!G54=0,'1. Inputs'!G54=""),"-",('1. Inputs'!H54-'1. Inputs'!G54)/ABS('1. Inputs'!G54)) -> - | I5: =IF(OR('1. Inputs'!H54=0,'1. Inputs'!H54=""),"-",('1. Inputs'!I54-'1. Inputs'!H54)/ABS('1. Inputs'!H54)) -> - | J5: =IF(OR('1. Inputs'!I54=0,'1. Inputs'!I54=""),"-",('1. Inputs'!J54-'1. Inputs'!I54)/ABS('1. Inputs'!I54)) -> - | ... L5: =IF(OR('1. Inputs'!K54=0,'1. Inputs'!K54=""),"-",('1. Inputs'!L54-'1. Inputs'!K54)/ABS('1. Inputs'!K54)) -> -
A6: CapEx (₹ Cr) | B6: ='1. Inputs'!B55 -> 0 | C6: ='1. Inputs'!C55 -> 0 | D6: ='1. Inputs'!D55 -> 0 | E6: ='1. Inputs'!E55 -> 0 | F6: ='1. Inputs'!F55 -> 0 | G6: ='1. Inputs'!G55 -> 0 | H6: ='1. Inputs'!H55 -> 0 | I6: ='1. Inputs'!I55 -> 0 | ... L6: ='1. Inputs'!L55 -> 0
A7: Free Cash Flow (₹ Cr) | B7: ='1. Inputs'!B54+'1. Inputs'!B55 -> 0 | C7: ='1. Inputs'!C54+'1. Inputs'!C55 -> 0 | D7: ='1. Inputs'!D54+'1. Inputs'!D55 -> 0 | E7: ='1. Inputs'!E54+'1. Inputs'!E55 -> 0 | F7: ='1. Inputs'!F54+'1. Inputs'!F55 -> 0 | G7: ='1. Inputs'!G54+'1. Inputs'!G55 -> 0 | H7: ='1. Inputs'!H54+'1. Inputs'!H55 -> 0 | I7: ='1. Inputs'!I54+'1. Inputs'!I55 -> 0 | ... L7: ='1. Inputs'!L54+'1. Inputs'!L55 -> 0
A8: FCF Margin % | B8: =IF(OR('1. Inputs'!B12=0,'1. Inputs'!B12=""),"-",('1. Inputs'!B54+'1. Inputs'!B55)/'1. Inputs'!B12) -> - | C8: =IF(OR('1. Inputs'!C12=0,'1. Inputs'!C12=""),"-",('1. Inputs'!C54+'1. Inputs'!C55)/'1. Inputs'!C12) -> - | D8: =IF(OR('1. Inputs'!D12=0,'1. Inputs'!D12=""),"-",('1. Inputs'!D54+'1. Inputs'!D55)/'1. Inputs'!D12) -> - | E8: =IF(OR('1. Inputs'!E12=0,'1. Inputs'!E12=""),"-",('1. Inputs'!E54+'1. Inputs'!E55)/'1. Inputs'!E12) -> - | F8: =IF(OR('1. Inputs'!F12=0,'1. Inputs'!F12=""),"-",('1. Inputs'!F54+'1. Inputs'!F55)/'1. Inputs'!F12) -> - | G8: =IF(OR('1. Inputs'!G12=0,'1. Inputs'!G12=""),"-",('1. Inputs'!G54+'1. Inputs'!G55)/'1. Inputs'!G12) -> - | H8: =IF(OR('1. Inputs'!H12=0,'1. Inputs'!H12=""),"-",('1. Inputs'!H54+'1. Inputs'!H55)/'1. Inputs'!H12) -> - | I8: =IF(OR('1. Inputs'!I12=0,'1. Inputs'!I12=""),"-",('1. Inputs'!I54+'1. Inputs'!I55)/'1. Inputs'!I12) -> - | ... L8: =IF(OR('1. Inputs'!L12=0,'1. Inputs'!L12=""),"-",('1. Inputs'!L54+'1. Inputs'!L55)/'1. Inputs'!L12) -> -
A9: FCF Per Share (₹) | B9: =IF('1. Inputs'!$B$5=0,"-",('1. Inputs'!B54+'1. Inputs'!B55)/'1. Inputs'!$B$5) -> - | C9: =IF('1. Inputs'!$B$5=0,"-",('1. Inputs'!C54+'1. Inputs'!C55)/'1. Inputs'!$B$5) -> - | D9: =IF('1. Inputs'!$B$5=0,"-",('1. Inputs'!D54+'1. Inputs'!D55)/'1. Inputs'!$B$5) -> - | E9: =IF('1. Inputs'!$B$5=0,"-",('1. Inputs'!E54+'1. Inputs'!E55)/'1. Inputs'!$B$5) -> - | F9: =IF('1. Inputs'!$B$5=0,"-",('1. Inputs'!F54+'1. Inputs'!F55)/'1. Inputs'!$B$5) -> - | G9: =IF('1. Inputs'!$B$5=0,"-",('1. Inputs'!G54+'1. Inputs'!G55)/'1. Inputs'!$B$5) -> - | H9: =IF('1. Inputs'!$B$5=0,"-",('1. Inputs'!H54+'1. Inputs'!H55)/'1. Inputs'!$B$5) -> - | I9: =IF('1. Inputs'!$B$5=0,"-",('1. Inputs'!I54+'1. Inputs'!I55)/'1. Inputs'!$B$5) -> - | ... L9: =IF('1. Inputs'!$B$5=0,"-",('1. Inputs'!L54+'1. Inputs'!L55)/'1. Inputs'!$B$5) -> -
A10: FCF Growth % | B10: N/A | C10: =IF(('1. Inputs'!B54+'1. Inputs'!B55)=0,"-",(('1. Inputs'!C54+'1. Inputs'!C55)-('1. Inputs'!B54+'1. Inputs'!B55))/ABS('1. Inputs'!B54+'1. Inputs'!B55)) -> - | D10: =IF(('1. Inputs'!C54+'1. Inputs'!C55)=0,"-",(('1. Inputs'!D54+'1. Inputs'!D55)-('1. Inputs'!C54+'1. Inputs'!C55))/ABS('1. Inputs'!C54+'1. Inputs'!C55)) -> - | E10: =IF(('1. Inputs'!D54+'1. Inputs'!D55)=0,"-",(('1. Inputs'!E54+'1. Inputs'!E55)-('1. Inputs'!D54+'1. Inputs'!D55))/ABS('1. Inputs'!D54+'1. Inputs'!D55)) -> - | F10: =IF(('1. Inputs'!E54+'1. Inputs'!E55)=0,"-",(('1. Inputs'!F54+'1. Inputs'!F55)-('1. Inputs'!E54+'1. Inputs'!E55))/ABS('1. Inputs'!E54+'1. Inputs'!E55)) -> - | G10: =IF(('1. Inputs'!F54+'1. Inputs'!F55)=0,"-",(('1. Inputs'!G54+'1. Inputs'!G55)-('1. Inputs'!F54+'1. Inputs'!F55))/ABS('1. Inputs'!F54+'1. Inputs'!F55)) -> - | H10: =IF(('1. Inputs'!G54+'1. Inputs'!G55)=0,"-",(('1. Inputs'!H54+'1. Inputs'!H55)-('1. Inputs'!G54+'1. Inputs'!G55))/ABS('1. Inputs'!G54+'1. Inputs'!G55)) -> - | I10: =IF(('1. Inputs'!H54+'1. Inputs'!H55)=0,"-",(('1. Inputs'!I54+'1. Inputs'!I55)-('1. Inputs'!H54+'1. Inputs'!H55))/ABS('1. Inputs'!H54+'1. Inputs'!H55)) -> - | J10: =IF(('1. Inputs'!I54+'1. Inputs'!I55)=0,"-",(('1. Inputs'!J54+'1. Inputs'!J55)-('1. Inputs'!I54+'1. Inputs'!I55))/ABS('1. Inputs'!I54+'1. Inputs'!I55)) -> - | ... L10: =IF(('1. Inputs'!K54+'1. Inputs'!K55)=0,"-",(('1. Inputs'!L54+'1. Inputs'!L55)-('1. Inputs'!K54+'1. Inputs'!K55))/ABS('1. Inputs'!K54+'1. Inputs'!K55)) -> -
A11: FCF / Net Income (Conversion) | B11: =IF(OR('1. Inputs'!B18=0,'1. Inputs'!B18=""),"-",('1. Inputs'!B54+'1. Inputs'!B55)/'1. Inputs'!B18) -> - | C11: =IF(OR('1. Inputs'!C18=0,'1. Inputs'!C18=""),"-",('1. Inputs'!C54+'1. Inputs'!C55)/'1. Inputs'!C18) -> - | D11: =IF(OR('1. Inputs'!D18=0,'1. Inputs'!D18=""),"-",('1. Inputs'!D54+'1. Inputs'!D55)/'1. Inputs'!D18) -> - | E11: =IF(OR('1. Inputs'!E18=0,'1. Inputs'!E18=""),"-",('1. Inputs'!E54+'1. Inputs'!E55)/'1. Inputs'!E18) -> - | F11: =IF(OR('1. Inputs'!F18=0,'1. Inputs'!F18=""),"-",('1. Inputs'!F54+'1. Inputs'!F55)/'1. Inputs'!F18) -> - | G11: =IF(OR('1. Inputs'!G18=0,'1. Inputs'!G18=""),"-",('1. Inputs'!G54+'1. Inputs'!G55)/'1. Inputs'!G18) -> - | H11: =IF(OR('1. Inputs'!H18=0,'1. Inputs'!H18=""),"-",('1. Inputs'!H54+'1. Inputs'!H55)/'1. Inputs'!H18) -> - | I11: =IF(OR('1. Inputs'!I18=0,'1. Inputs'!I18=""),"-",('1. Inputs'!I54+'1. Inputs'!I55)/'1. Inputs'!I18) -> - | ... L11: =IF(OR('1. Inputs'!L18=0,'1. Inputs'!L18=""),"-",('1. Inputs'!L54+'1. Inputs'!L55)/'1. Inputs'!L18) -> -
A12: SBC (₹ Cr) | B12: ='1. Inputs'!B58 -> 0 | C12: ='1. Inputs'!C58 -> 0 | D12: ='1. Inputs'!D58 -> 0 | E12: ='1. Inputs'!E58 -> 0 | F12: ='1. Inputs'!F58 -> 0 | G12: ='1. Inputs'!G58 -> 0 | H12: ='1. Inputs'!H58 -> 0 | I12: ='1. Inputs'!I58 -> 0 | ... L12: ='1. Inputs'!L58 -> 0
A13: SBC as % of Net Income | B13: =IF(OR('1. Inputs'!B18=0,'1. Inputs'!B18=""),"-",'1. Inputs'!B58/'1. Inputs'!B18) -> - | C13: =IF(OR('1. Inputs'!C18=0,'1. Inputs'!C18=""),"-",'1. Inputs'!C58/'1. Inputs'!C18) -> - | D13: =IF(OR('1. Inputs'!D18=0,'1. Inputs'!D18=""),"-",'1. Inputs'!D58/'1. Inputs'!D18) -> - | E13: =IF(OR('1. Inputs'!E18=0,'1. Inputs'!E18=""),"-",'1. Inputs'!E58/'1. Inputs'!E18) -> - | F13: =IF(OR('1. Inputs'!F18=0,'1. Inputs'!F18=""),"-",'1. Inputs'!F58/'1. Inputs'!F18) -> - | G13: =IF(OR('1. Inputs'!G18=0,'1. Inputs'!G18=""),"-",'1. Inputs'!G58/'1. Inputs'!G18) -> - | H13: =IF(OR('1. Inputs'!H18=0,'1. Inputs'!H18=""),"-",'1. Inputs'!H58/'1. Inputs'!H18) -> - | I13: =IF(OR('1. Inputs'!I18=0,'1. Inputs'!I18=""),"-",'1. Inputs'!I58/'1. Inputs'!I18) -> - | ... L13: =IF(OR('1. Inputs'!L18=0,'1. Inputs'!L18=""),"-",'1. Inputs'!L58/'1. Inputs'!L18) -> -
A14: Dividends Paid (₹ Cr) | B14: ='1. Inputs'!B60 -> 0 | C14: ='1. Inputs'!C60 -> 0 | D14: ='1. Inputs'!D60 -> 0 | E14: ='1. Inputs'!E60 -> 0 | F14: ='1. Inputs'!F60 -> 0 | G14: ='1. Inputs'!G60 -> 0 | H14: ='1. Inputs'!H60 -> 0 | I14: ='1. Inputs'!I60 -> 0 | ... L14: ='1. Inputs'!L60 -> 0
A15: Retained Earnings (₹ Cr) | B15: ='1. Inputs'!B18-ABS('1. Inputs'!B60) -> 0 | C15: ='1. Inputs'!C18-ABS('1. Inputs'!C60) -> 0 | D15: ='1. Inputs'!D18-ABS('1. Inputs'!D60) -> 0 | E15: ='1. Inputs'!E18-ABS('1. Inputs'!E60) -> 0 | F15: ='1. Inputs'!F18-ABS('1. Inputs'!F60) -> 0 | G15: ='1. Inputs'!G18-ABS('1. Inputs'!G60) -> 0 | H15: ='1. Inputs'!H18-ABS('1. Inputs'!H60) -> 0 | I15: ='1. Inputs'!I18-ABS('1. Inputs'!I60) -> 0 | ... L15: ='1. Inputs'!L18-ABS('1. Inputs'!L60) -> 0
A16: Retention Ratio % | B16: =IF(OR('1. Inputs'!B18=0,'1. Inputs'!B18=""),"-",1-ABS('1. Inputs'!B60)/'1. Inputs'!B18) -> - | C16: =IF(OR('1. Inputs'!C18=0,'1. Inputs'!C18=""),"-",1-ABS('1. Inputs'!C60)/'1. Inputs'!C18) -> - | D16: =IF(OR('1. Inputs'!D18=0,'1. Inputs'!D18=""),"-",1-ABS('1. Inputs'!D60)/'1. Inputs'!D18) -> - | E16: =IF(OR('1. Inputs'!E18=0,'1. Inputs'!E18=""),"-",1-ABS('1. Inputs'!E60)/'1. Inputs'!E18) -> - | F16: =IF(OR('1. Inputs'!F18=0,'1. Inputs'!F18=""),"-",1-ABS('1. Inputs'!F60)/'1. Inputs'!F18) -> - | G16: =IF(OR('1. Inputs'!G18=0,'1. Inputs'!G18=""),"-",1-ABS('1. Inputs'!G60)/'1. Inputs'!G18) -> - | H16: =IF(OR('1. Inputs'!H18=0,'1. Inputs'!H18=""),"-",1-ABS('1. Inputs'!H60)/'1. Inputs'!H18) -> - | I16: =IF(OR('1. Inputs'!I18=0,'1. Inputs'!I18=""),"-",1-ABS('1. Inputs'!I60)/'1. Inputs'!I18) -> - | ... L16: =IF(OR('1. Inputs'!L18=0,'1. Inputs'!L18=""),"-",1-ABS('1. Inputs'!L60)/'1. Inputs'!L18) -> -

Sheet 5. Returns & DuPont
A1: SECTION 6 & 14A: RETURN ON CAPITAL & DUPONT DECOMPOSITION
A3: Metric | B3: ='1. Inputs'!B11 -> 0 | C3: ='1. Inputs'!C11 -> 0 | D3: ='1. Inputs'!D11 -> 0 | E3: ='1. Inputs'!E11 -> 0 | F3: ='1. Inputs'!F11 -> 0 | G3: ='1. Inputs'!G11 -> 0 | H3: ='1. Inputs'!H11 -> 0 | I3: ='1. Inputs'!I11 -> 0 | ... L3: ='1. Inputs'!L11 -> 0
A4: ROE % | B4: =IF(OR('1. Inputs'!B34=0,'1. Inputs'!B34=""),"-",'1. Inputs'!B18/'1. Inputs'!B34) -> - | C4: =IF(OR(('1. Inputs'!C34+'1. Inputs'!B34)/2=0),"-",'1. Inputs'!C18/(('1. Inputs'!C34+'1. Inputs'!B34)/2)) -> - | D4: =IF(OR(('1. Inputs'!D34+'1. Inputs'!C34)/2=0),"-",'1. Inputs'!D18/(('1. Inputs'!D34+'1. Inputs'!C34)/2)) -> - | E4: =IF(OR(('1. Inputs'!E34+'1. Inputs'!D34)/2=0),"-",'1. Inputs'!E18/(('1. Inputs'!E34+'1. Inputs'!D34)/2)) -> - | F4: =IF(OR(('1. Inputs'!F34+'1. Inputs'!E34)/2=0),"-",'1. Inputs'!F18/(('1. Inputs'!F34+'1. Inputs'!E34)/2)) -> - | G4: =IF(OR(('1. Inputs'!G34+'1. Inputs'!F34)/2=0),"-",'1. Inputs'!G18/(('1. Inputs'!G34+'1. Inputs'!F34)/2)) -> - | H4: =IF(OR(('1. Inputs'!H34+'1. Inputs'!G34)/2=0),"-",'1. Inputs'!H18/(('1. Inputs'!H34+'1. Inputs'!G34)/2)) -> - | I4: =IF(OR(('1. Inputs'!I34+'1. Inputs'!H34)/2=0),"-",'1. Inputs'!I18/(('1. Inputs'!I34+'1. Inputs'!H34)/2)) -> - | J4: =IF(OR(('1. Inputs'!J34+'1. Inputs'!I34)/2=0),"-",'1. Inputs'!J18/(('1. Inputs'!J34+'1. Inputs'!I34)/2)) -> - | ... L4: =IF(OR(('1. Inputs'!L34+'1. Inputs'!K34)/2=0),"-",'1. Inputs'!L18/(('1. Inputs'!L34+'1. Inputs'!K34)/2)) -> -
A5: ROA % | B5: =IF(OR('1. Inputs'!B32=0,'1. Inputs'!B32=""),"-",'1. Inputs'!B18/'1. Inputs'!B32) -> - | C5: =IF(OR(('1. Inputs'!C32+'1. Inputs'!B32)/2=0),"-",'1. Inputs'!C18/(('1. Inputs'!C32+'1. Inputs'!B32)/2)) -> - | D5: =IF(OR(('1. Inputs'!D32+'1. Inputs'!C32)/2=0),"-",'1. Inputs'!D18/(('1. Inputs'!D32+'1. Inputs'!C32)/2)) -> - | E5: =IF(OR(('1. Inputs'!E32+'1. Inputs'!D32)/2=0),"-",'1. Inputs'!E18/(('1. Inputs'!E32+'1. Inputs'!D32)/2)) -> - | F5: =IF(OR(('1. Inputs'!F32+'1. Inputs'!E32)/2=0),"-",'1. Inputs'!F18/(('1. Inputs'!F32+'1. Inputs'!E32)/2)) -> - | G5: =IF(OR(('1. Inputs'!G32+'1. Inputs'!F32)/2=0),"-",'1. Inputs'!G18/(('1. Inputs'!G32+'1. Inputs'!F32)/2)) -> - | H5: =IF(OR(('1. Inputs'!H32+'1. Inputs'!G32)/2=0),"-",'1. Inputs'!H18/(('1. Inputs'!H32+'1. Inputs'!G32)/2)) -> - | I5: =IF(OR(('1. Inputs'!I32+'1. Inputs'!H32)/2=0),"-",'1. Inputs'!I18/(('1. Inputs'!I32+'1. Inputs'!H32)/2)) -> - | J5: =IF(OR(('1. Inputs'!J32+'1. Inputs'!I32)/2=0),"-",'1. Inputs'!J18/(('1. Inputs'!J32+'1. Inputs'!I32)/2)) -> - | ... L5: =IF(OR(('1. Inputs'!L32+'1. Inputs'!K32)/2=0),"-",'1. Inputs'!L18/(('1. Inputs'!L32+'1. Inputs'!K32)/2)) -> -
A6: --- DuPont Decomposition ---
A7: Net Profit Margin (NI/Rev) | B7: =IF(OR('1. Inputs'!B12=0,'1. Inputs'!B12=""),"-",'1. Inputs'!B18/'1. Inputs'!B12) -> - | C7: =IF(OR('1. Inputs'!C12=0,'1. Inputs'!C12=""),"-",'1. Inputs'!C18/'1. Inputs'!C12) -> - | D7: =IF(OR('1. Inputs'!D12=0,'1. Inputs'!D12=""),"-",'1. Inputs'!D18/'1. Inputs'!D12) -> - | E7: =IF(OR('1. Inputs'!E12=0,'1. Inputs'!E12=""),"-",'1. Inputs'!E18/'1. Inputs'!E12) -> - | F7: =IF(OR('1. Inputs'!F12=0,'1. Inputs'!F12=""),"-",'1. Inputs'!F18/'1. Inputs'!F12) -> - | G7: =IF(OR('1. Inputs'!G12=0,'1. Inputs'!G12=""),"-",'1. Inputs'!G18/'1. Inputs'!G12) -> - | H7: =IF(OR('1. Inputs'!H12=0,'1. Inputs'!H12=""),"-",'1. Inputs'!H18/'1. Inputs'!H12) -> - | I7: =IF(OR('1. Inputs'!I12=0,'1. Inputs'!I12=""),"-",'1. Inputs'!I18/'1. Inputs'!I12) -> - | ... L7: =IF(OR('1. Inputs'!L12=0,'1. Inputs'!L12=""),"-",'1. Inputs'!L18/'1. Inputs'!L12) -> -
A8: Asset Turnover (Rev/Avg Assets) | B8: =IF(OR('1. Inputs'!B32=0),"-",'1. Inputs'!B12/'1. Inputs'!B32) -> - | C8: =IF(OR(('1. Inputs'!C32+'1. Inputs'!B32)/2=0),"-",'1. Inputs'!C12/(('1. Inputs'!C32+'1. Inputs'!B32)/2)) -> - | D8: =IF(OR(('1. Inputs'!D32+'1. Inputs'!C32)/2=0),"-",'1. Inputs'!D12/(('1. Inputs'!D32+'1. Inputs'!C32)/2)) -> - | E8: =IF(OR(('1. Inputs'!E32+'1. Inputs'!D32)/2=0),"-",'1. Inputs'!E12/(('1. Inputs'!E32+'1. Inputs'!D32)/2)) -> - | F8: =IF(OR(('1. Inputs'!F32+'1. Inputs'!E32)/2=0),"-",'1. Inputs'!F12/(('1. Inputs'!F32+'1. Inputs'!E32)/2)) -> - | G8: =IF(OR(('1. Inputs'!G32+'1. Inputs'!F32)/2=0),"-",'1. Inputs'!G12/(('1. Inputs'!G32+'1. Inputs'!F32)/2)) -> - | H8: =IF(OR(('1. Inputs'!H32+'1. Inputs'!G32)/2=0),"-",'1. Inputs'!H12/(('1. Inputs'!H32+'1. Inputs'!G32)/2)) -> - | I8: =IF(OR(('1. Inputs'!I32+'1. Inputs'!H32)/2=0),"-",'1. Inputs'!I12/(('1. Inputs'!I32+'1. Inputs'!H32)/2)) -> - | J8: =IF(OR(('1. Inputs'!J32+'1. Inputs'!I32)/2=0),"-",'1. Inputs'!J12/(('1. Inputs'!J32+'1. Inputs'!I32)/2)) -> - | ... L8: =IF(OR(('1. Inputs'!L32+'1. Inputs'!K32)/2=0),"-",'1. Inputs'!L12/(('1. Inputs'!L32+'1. Inputs'!K32)/2)) -> -
A9: Equity Multiplier (Avg Assets/Avg Eq) | B9: =IF(OR('1. Inputs'!B34=0),"-",'1. Inputs'!B32/'1. Inputs'!B34) -> - | C9: =IF(OR(('1. Inputs'!C34+'1. Inputs'!B34)/2=0),"-",(('1. Inputs'!C32+'1. Inputs'!B32)/2)/(('1. Inputs'!C34+'1. Inputs'!B34)/2)) -> - | D9: =IF(OR(('1. Inputs'!D34+'1. Inputs'!C34)/2=0),"-",(('1. Inputs'!D32+'1. Inputs'!C32)/2)/(('1. Inputs'!D34+'1. Inputs'!C34)/2)) -> - | E9: =IF(OR(('1. Inputs'!E34+'1. Inputs'!D34)/2=0),"-",(('1. Inputs'!E32+'1. Inputs'!D32)/2)/(('1. Inputs'!E34+'1. Inputs'!D34)/2)) -> - | F9: =IF(OR(('1. Inputs'!F34+'1. Inputs'!E34)/2=0),"-",(('1. Inputs'!F32+'1. Inputs'!E32)/2)/(('1. Inputs'!F34+'1. Inputs'!E34)/2)) -> - | G9: =IF(OR(('1. Inputs'!G34+'1. Inputs'!F34)/2=0),"-",(('1. Inputs'!G32+'1. Inputs'!F32)/2)/(('1. Inputs'!G34+'1. Inputs'!F34)/2)) -> - | H9: =IF(OR(('1. Inputs'!H34+'1. Inputs'!G34)/2=0),"-",(('1. Inputs'!H32+'1. Inputs'!G32)/2)/(('1. Inputs'!H34+'1. Inputs'!G34)/2)) -> - | I9: =IF(OR(('1. Inputs'!I34+'1. Inputs'!H34)/2=0),"-",(('1. Inputs'!I32+'1. Inputs'!H32)/2)/(('1. Inputs'!I34+'1. Inputs'!H34)/2)) -> - | J9: =IF(OR(('1. Inputs'!J34+'1. Inputs'!I34)/2=0),"-",(('1. Inputs'!J32+'1. Inputs'!I32)/2)/(('1. Inputs'!J34+'1. Inputs'!I34)/2)) -> - | ... L9: =IF(OR(('1. Inputs'!L34+'1. Inputs'!K34)/2=0),"-",(('1. Inputs'!L32+'1. Inputs'!K32)/2)/(('1. Inputs'!L34+'1. Inputs'!K34)/2)) -> -
A10: DuPont ROE (Product) | B10: =IFERROR(B7*B8*B9,"-") -> - | C10: =IFERROR(C7*C8*C9,"-") -> - | D10: =IFERROR(D7*D8*D9,"-") -> - | E10: =IFERROR(E7*E8*E9,"-") -> - | F10: =IFERROR(F7*F8*F9,"-") -> - | G10: =IFERROR(G7*G8*G9,"-") -> - | H10: =IFERROR(H7*H8*H9,"-") -> - | I10: =IFERROR(I7*I8*I9,"-") -> - | ... L10: =IFERROR(L7*L8*L9,"-") -> -
A11: --- Additional Returns ---
A12: ROCE % (EBIT/Capital Employed) | B12: =IF(OR(('1. Inputs'!B34+'1. Inputs'!B35)=0),"-",('1. Inputs'!B13-'1. Inputs'!B14)/('1. Inputs'!B34+'1. Inputs'!B35)) -> - | C12: =IF(OR(('1. Inputs'!C34+'1. Inputs'!C35)=0),"-",('1. Inputs'!C13-'1. Inputs'!C14)/('1. Inputs'!C34+'1. Inputs'!C35)) -> - | D12: =IF(OR(('1. Inputs'!D34+'1. Inputs'!D35)=0),"-",('1. Inputs'!D13-'1. Inputs'!D14)/('1. Inputs'!D34+'1. Inputs'!D35)) -> - | E12: =IF(OR(('1. Inputs'!E34+'1. Inputs'!E35)=0),"-",('1. Inputs'!E13-'1. Inputs'!E14)/('1. Inputs'!E34+'1. Inputs'!E35)) -> - | F12: =IF(OR(('1. Inputs'!F34+'1. Inputs'!F35)=0),"-",('1. Inputs'!F13-'1. Inputs'!F14)/('1. Inputs'!F34+'1. Inputs'!F35)) -> - | G12: =IF(OR(('1. Inputs'!G34+'1. Inputs'!G35)=0),"-",('1. Inputs'!G13-'1. Inputs'!G14)/('1. Inputs'!G34+'1. Inputs'!G35)) -> - | H12: =IF(OR(('1. Inputs'!H34+'1. Inputs'!H35)=0),"-",('1. Inputs'!H13-'1. Inputs'!H14)/('1. Inputs'!H34+'1. Inputs'!H35)) -> - | I12: =IF(OR(('1. Inputs'!I34+'1. Inputs'!I35)=0),"-",('1. Inputs'!I13-'1. Inputs'!I14)/('1. Inputs'!I34+'1. Inputs'!I35)) -> - | ... L12: =IF(OR(('1. Inputs'!L34+'1. Inputs'!L35)=0),"-",('1. Inputs'!L13-'1. Inputs'!L14)/('1. Inputs'!L34+'1. Inputs'!L35)) -> -
A13: ROIC % (NOPAT/Invested Capital) | B13: =IF(OR(('1. Inputs'!B34+'1. Inputs'!B35-'1. Inputs'!B36)=0),"-",('1. Inputs'!B13-'1. Inputs'!B14)*(1-IFERROR('1. Inputs'!B17/'1. Inputs'!B16,0.25))/('1. Inputs'!B34+'1. Inputs'!B35-'1. Inputs'!B36)) -> - | C13: =IF(OR(('1. Inputs'!C34+'1. Inputs'!C35-'1. Inputs'!C36)=0),"-",('1. Inputs'!C13-'1. Inputs'!C14)*(1-IFERROR('1. Inputs'!C17/'1. Inputs'!C16,0.25))/('1. Inputs'!C34+'1. Inputs'!C35-'1. Inputs'!C36)) -> - | D13: =IF(OR(('1. Inputs'!D34+'1. Inputs'!D35-'1. Inputs'!D36)=0),"-",('1. Inputs'!D13-'1. Inputs'!D14)*(1-IFERROR('1. Inputs'!D17/'1. Inputs'!D16,0.25))/('1. Inputs'!D34+'1. Inputs'!D35-'1. Inputs'!D36)) -> - | E13: =IF(OR(('1. Inputs'!E34+'1. Inputs'!E35-'1. Inputs'!E36)=0),"-",('1. Inputs'!E13-'1. Inputs'!E14)*(1-IFERROR('1. Inputs'!E17/'1. Inputs'!E16,0.25))/('1. Inputs'!E34+'1. Inputs'!E35-'1. Inputs'!E36)) -> - | F13: =IF(OR(('1. Inputs'!F34+'1. Inputs'!F35-'1. Inputs'!F36)=0),"-",('1. Inputs'!F13-'1. Inputs'!F14)*(1-IFERROR('1. Inputs'!F17/'1. Inputs'!F16,0.25))/('1. Inputs'!F34+'1. Inputs'!F35-'1. Inputs'!F36)) -> - | G13: =IF(OR(('1. Inputs'!G34+'1. Inputs'!G35-'1. Inputs'!G36)=0),"-",('1. Inputs'!G13-'1. Inputs'!G14)*(1-IFERROR('1. Inputs'!G17/'1. Inputs'!G16,0.25))/('1. Inputs'!G34+'1. Inputs'!G35-'1. Inputs'!G36)) -> - | H13: =IF(OR(('1. Inputs'!H34+'1. Inputs'!H35-'1. Inputs'!H36)=0),"-",('1. Inputs'!H13-'1. Inputs'!H14)*(1-IFERROR('1. Inputs'!H17/'1. Inputs'!H16,0.25))/('1. Inputs'!H34+'1. Inputs'!H35-'1. Inputs'!H36)) -> - | I13: =IF(OR(('1. Inputs'!I34+'1. Inputs'!I35-'1. Inputs'!I36)=0),"-",('1. Inputs'!I13-'1. Inputs'!I14)*(1-IFERROR('1. Inputs'!I17/'1. Inputs'!I16,0.25))/('1. Inputs'!I34+'1. Inputs'!I35-'1. Inputs'!I36)) -> - | ... L13: =IF(OR(('1. Inputs'!L34+'1. Inputs'!L35-'1. Inputs'!L36)=0),"-",('1. Inputs'!L13-'1. Inputs'!L14)*(1-IFERROR('1. Inputs'!L17/'1. Inputs'!L16,0.25))/('1. Inputs'!L34+'1. Inputs'!L35-'1. Inputs'!L36)) -> -

Sheet 6. Scalability
A1: SECTION 8: SCALABILITY — Incremental Margins & Capital Efficiency
A3: Metric | B3: ='1. Inputs'!B11 -> 0 | C3: ='1. Inputs'!C11 -> 0 | D3: ='1. Inputs'!D11 -> 0 | E3: ='1. Inputs'!E11 -> 0 | F3: ='1. Inputs'!F11 -> 0 | G3: ='1. Inputs'!G11 -> 0 | H3: ='1. Inputs'!H11 -> 0 | I3: ='1. Inputs'!I11 -> 0 | ... L3: ='1. Inputs'!L11 -> 0
A4: Revenue (₹ Cr) | B4: ='1. Inputs'!B12 -> 0 | C4: ='1. Inputs'!C12 -> 0 | D4: ='1. Inputs'!D12 -> 0 | E4: ='1. Inputs'!E12 -> 0 | F4: ='1. Inputs'!F12 -> 0 | G4: ='1. Inputs'!G12 -> 0 | H4: ='1. Inputs'!H12 -> 0 | I4: ='1. Inputs'!I12 -> 0 | ... L4: ='1. Inputs'!L12 -> 0
A5: Revenue Growth % | B5: N/A | C5: =IF(OR('1. Inputs'!B12=0,'1. Inputs'!B12=""),"-",('1. Inputs'!C12-'1. Inputs'!B12)/ABS('1. Inputs'!B12)) -> - | D5: =IF(OR('1. Inputs'!C12=0,'1. Inputs'!C12=""),"-",('1. Inputs'!D12-'1. Inputs'!C12)/ABS('1. Inputs'!C12)) -> - | E5: =IF(OR('1. Inputs'!D12=0,'1. Inputs'!D12=""),"-",('1. Inputs'!E12-'1. Inputs'!D12)/ABS('1. Inputs'!D12)) -> - | F5: =IF(OR('1. Inputs'!E12=0,'1. Inputs'!E12=""),"-",('1. Inputs'!F12-'1. Inputs'!E12)/ABS('1. Inputs'!E12)) -> - | G5: =IF(OR('1. Inputs'!F12=0,'1. Inputs'!F12=""),"-",('1. Inputs'!G12-'1. Inputs'!F12)/ABS('1. Inputs'!F12)) -> - | H5: =IF(OR('1. Inputs'!G12=0,'1. Inputs'!G12=""),"-",('1. Inputs'!H12-'1. Inputs'!G12)/ABS('1. Inputs'!G12)) -> - | I5: =IF(OR('1. Inputs'!H12=0,'1. Inputs'!H12=""),"-",('1. Inputs'!I12-'1. Inputs'!H12)/ABS('1. Inputs'!H12)) -> - | J5: =IF(OR('1. Inputs'!I12=0,'1. Inputs'!I12=""),"-",('1. Inputs'!J12-'1. Inputs'!I12)/ABS('1. Inputs'!I12)) -> - | ... L5: =IF(OR('1. Inputs'!K12=0,'1. Inputs'!K12=""),"-",('1. Inputs'!L12-'1. Inputs'!K12)/ABS('1. Inputs'!K12)) -> -
A6: Op Profit (₹ Cr) | B6: ='1. Inputs'!B13 -> 0 | C6: ='1. Inputs'!C13 -> 0 | D6: ='1. Inputs'!D13 -> 0 | E6: ='1. Inputs'!E13 -> 0 | F6: ='1. Inputs'!F13 -> 0 | G6: ='1. Inputs'!G13 -> 0 | H6: ='1. Inputs'!H13 -> 0 | I6: ='1. Inputs'!I13 -> 0 | ... L6: ='1. Inputs'!L13 -> 0
A7: Op Profit Growth % | B7: N/A | C7: =IF(OR('1. Inputs'!B13=0,'1. Inputs'!B13=""),"-",('1. Inputs'!C13-'1. Inputs'!B13)/ABS('1. Inputs'!B13)) -> - | D7: =IF(OR('1. Inputs'!C13=0,'1. Inputs'!C13=""),"-",('1. Inputs'!D13-'1. Inputs'!C13)/ABS('1. Inputs'!C13)) -> - | E7: =IF(OR('1. Inputs'!D13=0,'1. Inputs'!D13=""),"-",('1. Inputs'!E13-'1. Inputs'!D13)/ABS('1. Inputs'!D13)) -> - | F7: =IF(OR('1. Inputs'!E13=0,'1. Inputs'!E13=""),"-",('1. Inputs'!F13-'1. Inputs'!E13)/ABS('1. Inputs'!E13)) -> - | G7: =IF(OR('1. Inputs'!F13=0,'1. Inputs'!F13=""),"-",('1. Inputs'!G13-'1. Inputs'!F13)/ABS('1. Inputs'!F13)) -> - | H7: =IF(OR('1. Inputs'!G13=0,'1. Inputs'!G13=""),"-",('1. Inputs'!H13-'1. Inputs'!G13)/ABS('1. Inputs'!G13)) -> - | I7: =IF(OR('1. Inputs'!H13=0,'1. Inputs'!H13=""),"-",('1. Inputs'!I13-'1. Inputs'!H13)/ABS('1. Inputs'!H13)) -> - | J7: =IF(OR('1. Inputs'!I13=0,'1. Inputs'!I13=""),"-",('1. Inputs'!J13-'1. Inputs'!I13)/ABS('1. Inputs'!I13)) -> - | ... L7: =IF(OR('1. Inputs'!K13=0,'1. Inputs'!K13=""),"-",('1. Inputs'!L13-'1. Inputs'!K13)/ABS('1. Inputs'!K13)) -> -
A8: Current Op Margin % | B8: =IF(OR('1. Inputs'!B12=0,'1. Inputs'!B12=""),"-",'1. Inputs'!B13/'1. Inputs'!B12) -> - | C8: =IF(OR('1. Inputs'!C12=0,'1. Inputs'!C12=""),"-",'1. Inputs'!C13/'1. Inputs'!C12) -> - | D8: =IF(OR('1. Inputs'!D12=0,'1. Inputs'!D12=""),"-",'1. Inputs'!D13/'1. Inputs'!D12) -> - | E8: =IF(OR('1. Inputs'!E12=0,'1. Inputs'!E12=""),"-",'1. Inputs'!E13/'1. Inputs'!E12) -> - | F8: =IF(OR('1. Inputs'!F12=0,'1. Inputs'!F12=""),"-",'1. Inputs'!F13/'1. Inputs'!F12) -> - | G8: =IF(OR('1. Inputs'!G12=0,'1. Inputs'!G12=""),"-",'1. Inputs'!G13/'1. Inputs'!G12) -> - | H8: =IF(OR('1. Inputs'!H12=0,'1. Inputs'!H12=""),"-",'1. Inputs'!H13/'1. Inputs'!H12) -> - | I8: =IF(OR('1. Inputs'!I12=0,'1. Inputs'!I12=""),"-",'1. Inputs'!I13/'1. Inputs'!I12) -> - | ... L8: =IF(OR('1. Inputs'!L12=0,'1. Inputs'!L12=""),"-",'1. Inputs'!L13/'1. Inputs'!L12) -> -
A9: Incremental Op Margin % | B9: N/A | C9: =IF(OR(('1. Inputs'!C12-'1. Inputs'!B12)=0),"-",('1. Inputs'!C13-'1. Inputs'!B13)/('1. Inputs'!C12-'1. Inputs'!B12)) -> - | D9: =IF(OR(('1. Inputs'!D12-'1. Inputs'!C12)=0),"-",('1. Inputs'!D13-'1. Inputs'!C13)/('1. Inputs'!D12-'1. Inputs'!C12)) -> - | E9: =IF(OR(('1. Inputs'!E12-'1. Inputs'!D12)=0),"-",('1. Inputs'!E13-'1. Inputs'!D13)/('1. Inputs'!E12-'1. Inputs'!D12)) -> - | F9: =IF(OR(('1. Inputs'!F12-'1. Inputs'!E12)=0),"-",('1. Inputs'!F13-'1. Inputs'!E13)/('1. Inputs'!F12-'1. Inputs'!E12)) -> - | G9: =IF(OR(('1. Inputs'!G12-'1. Inputs'!F12)=0),"-",('1. Inputs'!G13-'1. Inputs'!F13)/('1. Inputs'!G12-'1. Inputs'!F12)) -> - | H9: =IF(OR(('1. Inputs'!H12-'1. Inputs'!G12)=0),"-",('1. Inputs'!H13-'1. Inputs'!G13)/('1. Inputs'!H12-'1. Inputs'!G12)) -> - | I9: =IF(OR(('1. Inputs'!I12-'1. Inputs'!H12)=0),"-",('1. Inputs'!I13-'1. Inputs'!H13)/('1. Inputs'!I12-'1. Inputs'!H12)) -> - | J9: =IF(OR(('1. Inputs'!J12-'1. Inputs'!I12)=0),"-",('1. Inputs'!J13-'1. Inputs'!I13)/('1. Inputs'!J12-'1. Inputs'!I12)) -> - | ... L9: =IF(OR(('1. Inputs'!L12-'1. Inputs'!K12)=0),"-",('1. Inputs'!L13-'1. Inputs'!K13)/('1. Inputs'!L12-'1. Inputs'!K12)) -> -
A10: Inc. Margin / Current Margin | B10: N/A | C10: =IFERROR(C9/C8,"-") -> - | D10: =IFERROR(D9/D8,"-") -> - | E10: =IFERROR(E9/E8,"-") -> - | F10: =IFERROR(F9/F8,"-") -> - | G10: =IFERROR(G9/G8,"-") -> - | H10: =IFERROR(H9/H8,"-") -> - | I10: =IFERROR(I9/I8,"-") -> - | J10: =IFERROR(J9/J8,"-") -> - | ... L10: =IFERROR(L9/L8,"-") -> -
A11: CapEx as % of Revenue | B11: =IF(OR('1. Inputs'!B12=0,'1. Inputs'!B12=""),"-",ABS('1. Inputs'!B55)/'1. Inputs'!B12) -> - | C11: =IF(OR('1. Inputs'!C12=0,'1. Inputs'!C12=""),"-",ABS('1. Inputs'!C55)/'1. Inputs'!C12) -> - | D11: =IF(OR('1. Inputs'!D12=0,'1. Inputs'!D12=""),"-",ABS('1. Inputs'!D55)/'1. Inputs'!D12) -> - | E11: =IF(OR('1. Inputs'!E12=0,'1. Inputs'!E12=""),"-",ABS('1. Inputs'!E55)/'1. Inputs'!E12) -> - | F11: =IF(OR('1. Inputs'!F12=0,'1. Inputs'!F12=""),"-",ABS('1. Inputs'!F55)/'1. Inputs'!F12) -> - | G11: =IF(OR('1. Inputs'!G12=0,'1. Inputs'!G12=""),"-",ABS('1. Inputs'!G55)/'1. Inputs'!G12) -> - | H11: =IF(OR('1. Inputs'!H12=0,'1. Inputs'!H12=""),"-",ABS('1. Inputs'!H55)/'1. Inputs'!H12) -> - | I11: =IF(OR('1. Inputs'!I12=0,'1. Inputs'!I12=""),"-",ABS('1. Inputs'!I55)/'1. Inputs'!I12) -> - | ... L11: =IF(OR('1. Inputs'!L12=0,'1. Inputs'!L12=""),"-",ABS('1. Inputs'!L55)/'1. Inputs'!L12) -> -
A12: Revenue / CapEx (x) | B12: =IF(OR('1. Inputs'!B55=0),"-",'1. Inputs'!B12/ABS('1. Inputs'!B55)) -> - | C12: =IF(OR('1. Inputs'!C55=0),"-",'1. Inputs'!C12/ABS('1. Inputs'!C55)) -> - | D12: =IF(OR('1. Inputs'!D55=0),"-",'1. Inputs'!D12/ABS('1. Inputs'!D55)) -> - | E12: =IF(OR('1. Inputs'!E55=0),"-",'1. Inputs'!E12/ABS('1. Inputs'!E55)) -> - | F12: =IF(OR('1. Inputs'!F55=0),"-",'1. Inputs'!F12/ABS('1. Inputs'!F55)) -> - | G12: =IF(OR('1. Inputs'!G55=0),"-",'1. Inputs'!G12/ABS('1. Inputs'!G55)) -> - | H12: =IF(OR('1. Inputs'!H55=0),"-",'1. Inputs'!H12/ABS('1. Inputs'!H55)) -> - | I12: =IF(OR('1. Inputs'!I55=0),"-",'1. Inputs'!I12/ABS('1. Inputs'!I55)) -> - | ... L12: =IF(OR('1. Inputs'!L55=0),"-",'1. Inputs'!L12/ABS('1. Inputs'!L55)) -> -
A13: Asset Turnover | B13: =IF(OR('1. Inputs'!B32=0),"-",'1. Inputs'!B12/'1. Inputs'!B32) -> - | C13: =IF(OR('1. Inputs'!C32=0),"-",'1. Inputs'!C12/'1. Inputs'!C32) -> - | D13: =IF(OR('1. Inputs'!D32=0),"-",'1. Inputs'!D12/'1. Inputs'!D32) -> - | E13: =IF(OR('1. Inputs'!E32=0),"-",'1. Inputs'!E12/'1. Inputs'!E32) -> - | F13: =IF(OR('1. Inputs'!F32=0),"-",'1. Inputs'!F12/'1. Inputs'!F32) -> - | G13: =IF(OR('1. Inputs'!G32=0),"-",'1. Inputs'!G12/'1. Inputs'!G32) -> - | H13: =IF(OR('1. Inputs'!H32=0),"-",'1. Inputs'!H12/'1. Inputs'!H32) -> - | I13: =IF(OR('1. Inputs'!I32=0),"-",'1. Inputs'!I12/'1. Inputs'!I32) -> - | ... L13: =IF(OR('1. Inputs'!L32=0),"-",'1. Inputs'!L12/'1. Inputs'!L32) -> -

Sheet 7. Dollar Test
A1: SECTION 9: BUFFETT'S $1 TEST
A3: Period Start Year
A4: Period End Year
A5: Cumulative Net Income over period (₹ Cr)
A6: Cumulative Dividends Paid over period (₹ Cr)
A7: Cumulative Retained Earnings (₹ Cr) | B7: =B5-ABS(B6) -> 0
A8: Market Cap at Start (₹ Cr)
A9: Market Cap at End (₹ Cr)
A10: Change in Market Cap (₹ Cr) | B10: =B9-B8 -> 0
A11: $1 Test Result (Mkt Cap Change / Retained) | B11: =IF(B7=0,"-",B10/B7) -> -
A13: INTERPRETATION:
A14: > 1.0x → Management created more than ₹1 of market value per ₹1 retained — PASS
A15: ≈ 1.0x → Breakeven — market values retained earnings at par
A16: < 1.0x → Management destroyed value — FAIL

Sheet 8. Valuation Multiples
A1: SECTION 11: VALUATION MULTIPLES
A3: Note: Historical multiples require year-end prices. Enter below or compute from Screener data.
A5: CURRENT VALUATION SNAPSHOT | B5: Value | C5: Formula
A6: CMP (₹) | B6: ='1. Inputs'!B4 -> 0 | C6: Input
A7: TTM EPS (₹) | B7: ='1. Inputs'!L19 -> 0 | C7: Latest EPS from inputs
A8: TTM Net Profit (₹ Cr) | B8: ='1. Inputs'!L18 -> 0 | C8: Latest NP
A9: BVPS (₹) | B9: ='1. Inputs'!L39 -> 0 | C9: Latest BVPS
A10: TTM FCF (₹ Cr) | B10: ='1. Inputs'!L54+'1. Inputs'!L55 -> 0 | C10: CFO + CapEx
A11: TTM EBITDA (₹ Cr) | B11: ='1. Inputs'!L13 -> 0 | C11: Op Profit = EBITDA
A12: Shares (Cr) | B12: ='1. Inputs'!B5 -> 0 | C12: Diluted shares
A13: PE Ratio | B13: =IF(OR('1. Inputs'!L19=0,'1. Inputs'!L19=""),"-",'1. Inputs'!B4/'1. Inputs'!L19) -> - | C13: CMP / EPS
A14: P/B Ratio | B14: =IF(OR('1. Inputs'!L39=0,'1. Inputs'!L39=""),"-",'1. Inputs'!B4/'1. Inputs'!L39) -> - | C14: CMP / BVPS
A15: P/FCF | B15: =IF(OR(('1. Inputs'!L54+'1. Inputs'!L55)=0),"-",('1. Inputs'!B4*'1. Inputs'!B5)/('1. Inputs'!L54+'1. Inputs'!L55)) -> - | C15: MCap / FCF
A16: EV/EBITDA | B16: =IF(OR('1. Inputs'!L13=0,'1. Inputs'!L13=""),"-",('1. Inputs'!B4*'1. Inputs'!B5+'1. Inputs'!L35-'1. Inputs'!L36)/'1. Inputs'!L13) -> - | C16: (MCap+Debt-Cash)/EBITDA
A17: Earnings Yield % | B17: =IF(OR('1. Inputs'!B4=0),"-",'1. Inputs'!L19/'1. Inputs'!B4) -> - | C17: EPS / CMP
A18: FCF Yield % | B18: =IF(OR('1. Inputs'!B4=0),"-",('1. Inputs'!L54+'1. Inputs'!L55)/('1. Inputs'!B4*'1. Inputs'!B5)) -> - | C18: FCF / MCap
A19: Dividend Yield % | B19: =IF(OR('1. Inputs'!B4=0),"-",'1. Inputs'!L20/'1. Inputs'!B4) -> - | C19: DPS / CMP
A20: Market Cap (₹ Cr) | B20: ='1. Inputs'!B4*'1. Inputs'!B5 -> 0 | C20: CMP × Shares
A21: Enterprise Value (₹ Cr) | B21: ='1. Inputs'!B4*'1. Inputs'!B5+'1. Inputs'!L35-'1. Inputs'!L36 -> 0 | C21: MCap+Debt-Cash
A24: BANK MODE: FAIR P/B CALCULATION (Gordon Growth)
A25: Sustainable ROE %
A26: Cost of Equity (CoE) % | B26: 11
A27: Retention Ratio %
A28: Growth Rate g = ROE × Retention | B28: =B25/100*B27/100 -> 0
A29: Fair P/B = (ROE - g) / (CoE - g) | B29: =IF((B26/100-B28)=0,"-",(B25/100-B28)/(B26/100-B28)) -> 0

Sheet 9. DCF Intrinsic Value
A1: SECTION 12: DCF INTRINSIC VALUE (3 SCENARIOS)
A3: ASSUMPTIONS | B3: Conservative | C3: Base | D3: Optimistic
A4: Starting Owner Earnings (₹ Cr)
A5: Growth Rate Yr 1-5 % | B5: 8 | C5: 12 | D5: 18
A6: Growth Rate Yr 6-10 % | B6: 5 | C6: 8 | D6: 12
A7: Terminal Growth Rate % | B7: 4 | C7: 5 | D7: 5
A8: Discount Rate (WACC / Hurdle) % | B8: 12 | C8: 11 | D8: 10
A9: Net Debt (₹ Cr) [+debt, -cash]
A10: Shares Outstanding (Cr) | B10: ='1. Inputs'!B5 -> 0 | C10: ='1. Inputs'!B5 -> 0 | D10: ='1. Inputs'!B5 -> 0
A11: Current Market Price (₹) | B11: ='1. Inputs'!B4 -> 0 | C11: ='1. Inputs'!B4 -> 0 | D11: ='1. Inputs'!B4 -> 0
A14: DCF — Conservative Scenario
A15: Year | B15: Base | C15: Y1 | D15: Y2 | E15: Y3 | F15: Y4 | G15: Y5 | H15: Y6 | I15: Y7 | J15: Y8 | K15: Y9 | L15: Y10 | M15: Terminal
A16: Owner Earnings (₹ Cr) | B16: =B4 -> 0 | C16: =B16*(1+$B$5/100) -> 0 | D16: =C16*(1+$B$5/100) -> 0 | E16: =D16*(1+$B$5/100) -> 0 | F16: =E16*(1+$B$5/100) -> 0 | G16: =F16*(1+$B$5/100) -> 0 | H16: =G16*(1+$B$6/100) -> 0 | I16: =H16*(1+$B$6/100) -> 0 | J16: =I16*(1+$B$6/100) -> 0 | K16: =J16*(1+$B$6/100) -> 0 | L16: =K16*(1+$B$6/100) -> 0 | M16: =L16*(1+$B$7/100)/($B$8/100-$B$7/100) -> 0
A17: Discount Factor | B17: 1 | C17: =1/(1+$B$8/100)^1 -> 0.89285714 | D17: =1/(1+$B$8/100)^2 -> 0.79719388 | E17: =1/(1+$B$8/100)^3 -> 0.71178025 | F17: =1/(1+$B$8/100)^4 -> 0.63551808 | G17: =1/(1+$B$8/100)^5 -> 0.56742686 | H17: =1/(1+$B$8/100)^6 -> 0.50663112 | I17: =1/(1+$B$8/100)^7 -> 0.45234922 | J17: =1/(1+$B$8/100)^8 -> 0.40388323 | K17: =1/(1+$B$8/100)^9 -> 0.36061002 | L17: =1/(1+$B$8/100)^10 -> 0.32197324 | M17: =1/(1+$B$8/100)^10 -> 0.32197324
A18: PV of Cash Flow (₹ Cr) | C18: =C16*C17 -> 0 | D18: =D16*D17 -> 0 | E18: =E16*E17 -> 0 | F18: =F16*F17 -> 0 | G18: =G16*G17 -> 0 | H18: =H16*H17 -> 0 | I18: =I16*I17 -> 0 | J18: =J16*J17 -> 0 | ... M18: =M16*M17 -> 0
A20: PV of 10-Year Cash Flows (₹ Cr) | B20: =SUM(C18:L18) -> 0
A21: PV of Terminal Value (₹ Cr) | B21: =M18 -> 0
A22: Total Enterprise Value (₹ Cr) | B22: =B20+B21 -> 0
A23: Less: Net Debt (₹ Cr) | B23: =$B$9 -> 0
A24: Equity Value (₹ Cr) | B24: =B22-B23 -> 0
A25: Intrinsic Value Per Share (₹) | B25: =IF($B$10=0,"-",B24/$B$10) -> -
A26: Margin of Safety (IV-CMP)/IV | B26: =IFERROR((B25-$B$11)/B25,"-") -> -
A27: Upside from CMP % | B27: =IF($B$11=0,"-",(B25-$B$11)/$B$11) -> -
A32: DCF — Base Scenario
A33: Year | B33: Base | C33: Y1 | D33: Y2 | E33: Y3 | F33: Y4 | G33: Y5 | H33: Y6 | I33: Y7 | J33: Y8 | K33: Y9 | L33: Y10 | M33: Terminal
A34: Owner Earnings (₹ Cr) | B34: =C4 -> 0 | C34: =B34*(1+$C$5/100) -> 0 | D34: =C34*(1+$C$5/100) -> 0 | E34: =D34*(1+$C$5/100) -> 0 | F34: =E34*(1+$C$5/100) -> 0 | G34: =F34*(1+$C$5/100) -> 0 | H34: =G34*(1+$C$6/100) -> 0 | I34: =H34*(1+$C$6/100) -> 0 | J34: =I34*(1+$C$6/100) -> 0 | K34: =J34*(1+$C$6/100) -> 0 | L34: =K34*(1+$C$6/100) -> 0 | M34: =L34*(1+$C$7/100)/($C$8/100-$C$7/100) -> 0
A35: Discount Factor | B35: 1 | C35: =1/(1+$C$8/100)^1 -> 0.9009009 | D35: =1/(1+$C$8/100)^2 -> 0.81162243 | E35: =1/(1+$C$8/100)^3 -> 0.73119138 | F35: =1/(1+$C$8/100)^4 -> 0.65873097 | G35: =1/(1+$C$8/100)^5 -> 0.59345133 | H35: =1/(1+$C$8/100)^6 -> 0.53464084 | I35: =1/(1+$C$8/100)^7 -> 0.48165841 | J35: =1/(1+$C$8/100)^8 -> 0.4339265 | K35: =1/(1+$C$8/100)^9 -> 0.39092477 | L35: =1/(1+$C$8/100)^10 -> 0.35218448 | M35: =1/(1+$C$8/100)^10 -> 0.35218448
A36: PV of Cash Flow (₹ Cr) | C36: =C34*C35 -> 0 | D36: =D34*D35 -> 0 | E36: =E34*E35 -> 0 | F36: =F34*F35 -> 0 | G36: =G34*G35 -> 0 | H36: =H34*H35 -> 0 | I36: =I34*I35 -> 0 | J36: =J34*J35 -> 0 | ... M36: =M34*M35 -> 0
A38: PV of 10-Year Cash Flows (₹ Cr) | B38: =SUM(C36:L36) -> 0
A39: PV of Terminal Value (₹ Cr) | B39: =M36 -> 0
A40: Total Enterprise Value (₹ Cr) | B40: =B38+B39 -> 0
A41: Less: Net Debt (₹ Cr) | B41: =$C$9 -> 0
A42: Equity Value (₹ Cr) | B42: =B40-B41 -> 0
A43: Intrinsic Value Per Share (₹) | B43: =IF($C$10=0,"-",B42/$C$10) -> -
A44: Margin of Safety (IV-CMP)/IV | B44: =IFERROR((B43-$C$11)/B43,"-") -> -
A45: Upside from CMP % | B45: =IF($C$11=0,"-",(B43-$C$11)/$C$11) -> -
A50: DCF — Optimistic Scenario
A51: Year | B51: Base | C51: Y1 | D51: Y2 | E51: Y3 | F51: Y4 | G51: Y5 | H51: Y6 | I51: Y7 | J51: Y8 | K51: Y9 | L51: Y10 | M51: Terminal
A52: Owner Earnings (₹ Cr) | B52: =D4 -> 0 | C52: =B52*(1+$D$5/100) -> 0 | D52: =C52*(1+$D$5/100) -> 0 | E52: =D52*(1+$D$5/100) -> 0 | F52: =E52*(1+$D$5/100) -> 0 | G52: =F52*(1+$D$5/100) -> 0 | H52: =G52*(1+$D$6/100) -> 0 | I52: =H52*(1+$D$6/100) -> 0 | J52: =I52*(1+$D$6/100) -> 0 | K52: =J52*(1+$D$6/100) -> 0 | L52: =K52*(1+$D$6/100) -> 0 | M52: =L52*(1+$D$7/100)/($D$8/100-$D$7/100) -> 0
A53: Discount Factor | B53: 1 | C53: =1/(1+$D$8/100)^1 -> 0.90909091 | D53: =1/(1+$D$8/100)^2 -> 0.82644628 | E53: =1/(1+$D$8/100)^3 -> 0.7513148 | F53: =1/(1+$D$8/100)^4 -> 0.68301346 | G53: =1/(1+$D$8/100)^5 -> 0.62092132 | H53: =1/(1+$D$8/100)^6 -> 0.56447393 | I53: =1/(1+$D$8/100)^7 -> 0.51315812 | J53: =1/(1+$D$8/100)^8 -> 0.46650738 | K53: =1/(1+$D$8/100)^9 -> 0.42409762 | L53: =1/(1+$D$8/100)^10 -> 0.38554329 | M53: =1/(1+$D$8/100)^10 -> 0.38554329
...

Sheet 10. Reverse DCF
A1: SECTION 13: REVERSE DCF — Implied EPS CAGR
A3: INPUTS
A4: CMP (₹) | B4: ='1. Inputs'!B4 -> 0
A5: TTM Normalised EPS (₹) | B5: ='1. Inputs'!L19 -> 0
A6: Current PE | B6: =IF(OR('1. Inputs'!L19=0,'1. Inputs'!L19=""),"-",'1. Inputs'!B4/'1. Inputs'!L19) -> -
A8: TERMINAL PE SCENARIOS | B8: Mature (15x) | C8: Market (20x) | D8: Compounder (28x) | E8: Historical Avg
A9: Terminal PE Value | B9: 15 | C9: 20 | D9: 28 | E9: ='1. Inputs'!B63 -> 0
A11: At Terminal PE = Mature (15x) | B11: 10% Return | C11: 15% Return | D11: 20% Return
A12: 5 Years | B12: =IFERROR((($B4*(1+10/100)^5/B9)/$B5)^(1/5)-1,"-") -> - | C12: =IFERROR((($B4*(1+15/100)^5/B9)/$B5)^(1/5)-1,"-") -> - | D12: =IFERROR((($B4*(1+20/100)^5/B9)/$B5)^(1/5)-1,"-") -> -
A13: 10 Years | B13: =IFERROR((($B4*(1+10/100)^10/B9)/$B5)^(1/10)-1,"-") -> - | C13: =IFERROR((($B4*(1+15/100)^10/B9)/$B5)^(1/10)-1,"-") -> - | D13: =IFERROR((($B4*(1+20/100)^10/B9)/$B5)^(1/10)-1,"-") -> -
A14: 15 Years | B14: =IFERROR((($B4*(1+10/100)^15/B9)/$B5)^(1/15)-1,"-") -> - | C14: =IFERROR((($B4*(1+15/100)^15/B9)/$B5)^(1/15)-1,"-") -> - | D14: =IFERROR((($B4*(1+20/100)^15/B9)/$B5)^(1/15)-1,"-") -> -
A18: At Terminal PE = Market Avg (20x) | B18: 10% Return | C18: 15% Return | D18: 20% Return
A19: 5 Years | B19: =IFERROR((($B4*(1+10/100)^5/C9)/$B5)^(1/5)-1,"-") -> - | C19: =IFERROR((($B4*(1+15/100)^5/C9)/$B5)^(1/5)-1,"-") -> - | D19: =IFERROR((($B4*(1+20/100)^5/C9)/$B5)^(1/5)-1,"-") -> -
A20: 10 Years | B20: =IFERROR((($B4*(1+10/100)^10/C9)/$B5)^(1/10)-1,"-") -> - | C20: =IFERROR((($B4*(1+15/100)^10/C9)/$B5)^(1/10)-1,"-") -> - | D20: =IFERROR((($B4*(1+20/100)^10/C9)/$B5)^(1/10)-1,"-") -> -
A21: 15 Years | B21: =IFERROR((($B4*(1+10/100)^15/C9)/$B5)^(1/15)-1,"-") -> - | C21: =IFERROR((($B4*(1+15/100)^15/C9)/$B5)^(1/15)-1,"-") -> - | D21: =IFERROR((($B4*(1+20/100)^15/C9)/$B5)^(1/15)-1,"-") -> -
A25: At Terminal PE = Compounder (28x) | B25: 10% Return | C25: 15% Return | D25: 20% Return
A26: 5 Years | B26: =IFERROR((($B4*(1+10/100)^5/D9)/$B5)^(1/5)-1,"-") -> - | C26: =IFERROR((($B4*(1+15/100)^5/D9)/$B5)^(1/5)-1,"-") -> - | D26: =IFERROR((($B4*(1+20/100)^5/D9)/$B5)^(1/5)-1,"-") -> -
A27: 10 Years | B27: =IFERROR((($B4*(1+10/100)^10/D9)/$B5)^(1/10)-1,"-") -> - | C27: =IFERROR((($B4*(1+15/100)^10/D9)/$B5)^(1/10)-1,"-") -> - | D27: =IFERROR((($B4*(1+20/100)^10/D9)/$B5)^(1/10)-1,"-") -> -
A28: 15 Years | B28: =IFERROR((($B4*(1+10/100)^15/D9)/$B5)^(1/15)-1,"-") -> - | C28: =IFERROR((($B4*(1+15/100)^15/D9)/$B5)^(1/15)-1,"-") -> - | D28: =IFERROR((($B4*(1+20/100)^15/D9)/$B5)^(1/15)-1,"-") -> -
A32: At Terminal PE = Historical Avg | B32: 10% Return | C32: 15% Return | D32: 20% Return
A33: 5 Years | B33: =IFERROR((($B4*(1+10/100)^5/E9)/$B5)^(1/5)-1,"-") -> - | C33: =IFERROR((($B4*(1+15/100)^5/E9)/$B5)^(1/5)-1,"-") -> - | D33: =IFERROR((($B4*(1+20/100)^5/E9)/$B5)^(1/5)-1,"-") -> -
